Workbook

Sheet Payroll Register
A2: PAYROLL REGISTER
A3: Payroll Period: | D3: ='Raw Sheet'!D2 -> 46023 | E3: ='Raw Sheet'!E2 -> 46037
A5: No. | C5: Name of Employees | D5: Monthly Basic Salary | E5: Semi-Monthly Basic Salary | F5: DE MINIMIS BENEFIT | L5: Other Non-Taxable Compensation | M5: Salary Adjustment | N5: Overtime | O5: NSD | P5: Absences / Tardiness | Q5: Holiday Pay | R5: Gross Compensation | S5: Gross Taxable Compensation | T5: Non-Taxable Compensation | U5: EMPLOYEE'S SHARE | Z5: Regular Net Taxable Compensation | AA5: Withholding Tax Computation | AF5: Withholding Tax Due | AG5: SSS Loan | AJ5: Advances to Employees | AK5: 2025 Tax Refund | AL5: Non-Taxable Compensation | AM5: NET PAY | AW5: Monthly Gross Compensation | AX5: SSS Contribution | AY5: PHIC Contribution | AZ5: HDMF Contribution
F6: YEAR END GIFTS | G6: Rice Subsidy | H6: Uniform/Clothing Allowance | I6: Laundry Allowance | J6: Meal Allowance | K6: Medical Allowance | AA6: Bracket | AB6: Basic | AC6: % | AD6: Basic | AE6: Excess | AG6: Salary | AH6: Calamity | AI6: HDMF Loan | AN6: EMPLOYER'S SHARE
U7: SSS - RSS | V7: SSS - WISP | W7: SSS - TOTAL | X7: PHIC | Y7: HDMF | AN7: SSS-RSS | AO7: SSS-EC | AP7: SSS-WISP | AQ7: SSS-TOTAL | AR7: PHIC | AS7: HDMF
A8: 1 | B8: 3 | C8: A | D8: =VLOOKUP(B8,'Raw Sheet'!$B$8:$G$28,6,FALSE) -> 37200 | E8: =D8/2 -> 18600 | F8: 0 | G8: =VLOOKUP(B8,'Raw Sheet'!$B$8:$L$28,11,FALSE)/2 -> 1000 | H8: =VLOOKUP(B8,'Raw Sheet'!$B$8:$M$28,12,FALSE)/2 -> 250 | I8: =VLOOKUP(B8,'Raw Sheet'!$B$8:$N$28,13,FALSE)/2 -> 150 | J8: 0 | K8: 0 | L8: 0 | M8: 0 | N8: ='Raw Sheet'!AH8+'Raw Sheet'!AL8 -> 0 | O8: =SUM('Raw Sheet'!AJ8,'Raw Sheet'!AP8,'Raw Sheet'!BB8,'Raw Sheet'!BH8) -> 256.55172 | P8: ='Raw Sheet'!BJ8 -> 0 | Q8: ='Raw Sheet'!BD8 -> 0 | R8: =E8+SUM(F8:Q8) -> 20256.552 | S8: =E8+SUM(M8:Q8) -> 18856.552 | T8: =SUM(F8:L8) -> 1400 | Z8: =S8-SUM(W8:Y8) -> 18856.552 | AA8: =IF(Z8>=333333,"333333",IF(Z8>=83333,"83333",IF(Z8>=33333,"33333",IF(Z8>=16667,"16667",IF(Z8>=10417,"10417",IF(Z8<10417,"0")))))) -> 16667 | AB8: =AA8+0 -> 16667 | AC8: =VLOOKUP(AB8,WTAX!E:F,2,0) -> 0.2 | AD8: =VLOOKUP(AB8,WTAX!E:G,3,0) -> 937.5 | AE8: =(Z8-AB8)*AC8 -> 437.91034 | AF8: =AD8+AE8 -> 1375.4103 | AG8: =VLOOKUP(B8,'Raw Sheet'!$B$8:$V$28,21,FALSE) -> 1845.8 | AH8: =VLOOKUP(B8,'Raw Sheet'!$B$8:$W$28,22,FALSE) -> 0 | AI8: =VLOOKUP(B8,'Raw Sheet'!$B$8:$X$28,23,FALSE) -> 0 | AJ8: =VLOOKUP(B8,'Raw Sheet'!$B$8:$Y$28,24,FALSE) -> 0 | AK8: =[1]Haguimit!$D$44 -> -0.00068965516 | AL8: =T8 -> 1400 | AM8: =Z8-SUM(AF8:AJ8)+SUM(AK8:AL8) -> 17035.341 | AN8: 0 | AO8: 0 | AP8: 0 | AQ8: 0 | AR8: 0 | AS8: 0 | AW8: =SUM(AU8:AV8) -> 0 | AX8: =AQ8+W8 -> 0 | AZ8: =SUM(Y8,AS8) -> 0
A9: 8 | B9: 17 | C9: B | D9: =VLOOKUP(B9,'Raw Sheet'!$B$8:$G$28,6,FALSE) -> 45000 | E9: =D9/2 -> 22500 | F9: 0 | G9: =VLOOKUP(B9,'Raw Sheet'!$B$8:$L$28,11,FALSE)/2 -> 0 | H9: =VLOOKUP(B9,'Raw Sheet'!$B$8:$M$28,12,FALSE)/2 -> 0 | I9: =VLOOKUP(B9,'Raw Sheet'!$B$8:$N$28,13,FALSE)/2 -> 0 | J9: 0 | K9: 0 | L9: 0 | M9: 0 | N9: ='Raw Sheet'!AH9+'Raw Sheet'!AL9 -> 2909.4828 | O9: =SUM('Raw Sheet'!AJ9,'Raw Sheet'!AP9,'Raw Sheet'!BB9,'Raw Sheet'!BH9) -> 879.31034 | P9: ='Raw Sheet'!BJ9 -> 0 | Q9: ='Raw Sheet'!BD9 -> 2068.9655 | R9: =E9+SUM(F9:Q9) -> 28357.759 | S9: =E9+SUM(M9:Q9) -> 28357.759 | T9: =SUM(F9:L9) -> 0 | Z9: =S9-SUM(W9:Y9) -> 28357.759 | AA9: =IF(Z9>=333333,"333333",IF(Z9>=83333,"83333",IF(Z9>=33333,"33333",IF(Z9>=16667,"16667",IF(Z9>=10417,"10417",IF(Z9<10417,"0")))))) -> 16667 | AB9: =AA9+0 -> 16667 | AC9: =VLOOKUP(AB9,WTAX!E:F,2,0) -> 0.2 | AD9: =VLOOKUP(AB9,WTAX!E:G,3,0) -> 937.5 | AE9: =(Z9-AB9)*AC9 -> 2338.1517 | AF9: =AD9+AE9 -> 3275.6517 | AG9: =VLOOKUP(B9,'Raw Sheet'!$B$8:$V$28,21,FALSE) -> 922.9 | AH9: =VLOOKUP(B9,'Raw Sheet'!$B$8:$W$28,22,FALSE) -> 0 | AI9: =VLOOKUP(B9,'Raw Sheet'!$B$8:$X$28,23,FALSE) -> 0 | AJ9: =VLOOKUP(B9,'Raw Sheet'!$B$8:$Y$28,24,FALSE) -> 0 | AK9: =[1]Viray!$D$44 -> -0.0037931035 | AL9: =T9 -> 0 | AM9: =Z9-SUM(AF9:AJ9)+SUM(AK9:AL9) -> 24159.203 | AN9: 0 | AO9: 0 | AP9: 0 | AQ9: 0 | AR9: 0 | AS9: 0 | AW9: =SUM(AU9:AV9) -> 0 | AX9: =AQ9+W9 -> 0 | AZ9: =SUM(Y9,AS9) -> 0
A10: 10 | B10: 21 | C10: C | D10: =VLOOKUP(B10,'Raw Sheet'!$B$8:$G$28,6,FALSE) -> 42000 | E10: =D10/2 -> 21000 | F10: 0 | G10: =VLOOKUP(B10,'Raw Sheet'!$B$8:$L$28,11,FALSE)/2 -> 1000 | H10: =VLOOKUP(B10,'Raw Sheet'!$B$8:$M$28,12,FALSE)/2 -> 50 | I10: =VLOOKUP(B10,'Raw Sheet'!$B$8:$N$28,13,FALSE)/2 -> 0 | J10: 0 | K10: 0 | L10: 0 | M10: 0 | N10: ='Raw Sheet'!AH10+'Raw Sheet'!AL10 -> 3620.6897 | O10: =SUM('Raw Sheet'!AJ10,'Raw Sheet'!AP10,'Raw Sheet'!BB10,'Raw Sheet'!BH10) -> 0 | P10: ='Raw Sheet'!BJ10 -> 0 | Q10: ='Raw Sheet'!BD10 -> 0 | R10: =E10+SUM(F10:Q10) -> 25670.69 | S10: =E10+SUM(M10:Q10) -> 24620.69 | T10: =SUM(F10:L10) -> 1050 | Z10: =S10-SUM(W10:Y10) -> 24620.69 | AA10: =IF(Z10>=333333,"333333",IF(Z10>=83333,"83333",IF(Z10>=33333,"33333",IF(Z10>=16667,"16667",IF(Z10>=10417,"10417",IF(Z10<10417,"0")))))) -> 16667 | AB10: =AA10+0 -> 16667 | AC10: =VLOOKUP(AB10,WTAX!E:F,2,0) -> 0.2 | AD10: =VLOOKUP(AB10,WTAX!E:G,3,0) -> 937.5 | AE10: =(Z10-AB10)*AC10 -> 1590.7379 | AF10: =AD10+AE10 -> 2528.2379 | AG10: =VLOOKUP(B10,'Raw Sheet'!$B$8:$V$28,21,FALSE) -> 922.9 | AH10: =VLOOKUP(B10,'Raw Sheet'!$B$8:$W$28,22,FALSE) -> 0 | AI10: =VLOOKUP(B10,'Raw Sheet'!$B$8:$X$28,23,FALSE) -> 0 | AJ10: =VLOOKUP(B10,'Raw Sheet'!$B$8:$Y$28,24,FALSE) -> 0 | AK10: =[1]Dy!$D$44 -> 0.0037931035 | AL10: =T10 -> 1050 | AM10: =Z10-SUM(AF10:AJ10)+SUM(AK10:AL10) -> 22219.556 | AN10: 0 | AO10: 0 | AP10: 0 | AQ10: 0 | AR10: 0 | AS10: 0 | AW10: =SUM(AU10:AV10) -> 0 | AX10: =AQ10+W10 -> 0 | AZ10: =SUM(Y10,AS10) -> 0
A11: 11 | B11: 23 | C11: D | D11: =VLOOKUP(B11,'Raw Sheet'!$B$8:$G$28,6,FALSE) -> 169600 | E11: =D11/2 -> 84800 | F11: 0 | G11: =VLOOKUP(B11,'Raw Sheet'!$B$8:$L$28,11,FALSE)/2 -> 1000 | H11: =VLOOKUP(B11,'Raw Sheet'!$B$8:$M$28,12,FALSE)/2 -> 250 | I11: =VLOOKUP(B11,'Raw Sheet'!$B$8:$N$28,13,FALSE)/2 -> 150 | J11: 0 | K11: 0 | L11: 0 | M11: 0 | N11: ='Raw Sheet'!AH11+'Raw Sheet'!AL11 -> 0 | O11: =SUM('Raw Sheet'!AJ11,'Raw Sheet'!AP11,'Raw Sheet'!BB11,'Raw Sheet'!BH11) -> 0 | P11: ='Raw Sheet'!BJ11 -> 0 | Q11: ='Raw Sheet'!BD11 -> 0 | R11: =E11+SUM(F11:Q11) -> 86200 | S11: =E11+SUM(M11:Q11) -> 84800 | T11: =SUM(F11:L11) -> 1400 | Z11: =S11-SUM(W11:Y11) -> 84800 | AA11: =IF(Z11>=333333,"333333",IF(Z11>=83333,"83333",IF(Z11>=33333,"33333",IF(Z11>=16667,"16667",IF(Z11>=10417,"10417",IF(Z11<10417,"0")))))) -> 83333 | AB11: =AA11+0 -> 83333 | AC11: =VLOOKUP(AB11,WTAX!E:F,2,0) -> 0.3 | AD11: =VLOOKUP(AB11,WTAX!E:G,3,0) -> 16770.7 | AE11: =(Z11-AB11)*AC11 -> 440.1 | AF11: =AD11+AE11 -> 17210.8 | AG11: =VLOOKUP(B11,'Raw Sheet'!$B$8:$V$28,21,FALSE) -> 0 | AH11: =VLOOKUP(B11,'Raw Sheet'!$B$8:$W$28,22,FALSE) -> 0 | AI11: =VLOOKUP(B11,'Raw Sheet'!$B$8:$X$28,23,FALSE) -> 0 | AJ11: =VLOOKUP(B11,'Raw Sheet'!$B$8:$Y$28,24,FALSE) -> 0 | AK11: =[1]Marquez!$D$44 -> 0 | AL11: =T11 -> 1400 | AM11: =Z11-SUM(AF11:AJ11)+SUM(AK11:AL11) -> 68989.2 | AN11: 0 | AO11: 0 | AP11: 0 | AQ11: 0 | AR11: 0 | AS11: 0 | AW11: =SUM(AU11:AV11) -> 0 | AX11: =AQ11+W11 -> 0 | AZ11: =SUM(Y11,AS11) -> 0
A12: 12 | B12: 25 | C12: E | D12: =VLOOKUP(B12,'Raw Sheet'!$B$8:$G$28,6,FALSE) -> 255600 | E12: =D12/2 -> 127800 | F12: 0 | G12: =VLOOKUP(B12,'Raw Sheet'!$B$8:$L$28,11,FALSE)/2 -> 1000 | H12: =VLOOKUP(B12,'Raw Sheet'!$B$8:$M$28,12,FALSE)/2 -> 250 | I12: =VLOOKUP(B12,'Raw Sheet'!$B$8:$N$28,13,FALSE)/2 -> 150 | J12: 0 | K12: 0 | L12: 0 | M12: 0 | N12: ='Raw Sheet'!AH12+'Raw Sheet'!AL12 -> 0 | O12: =SUM('Raw Sheet'!AJ12,'Raw Sheet'!AP12,'Raw Sheet'!BB12,'Raw Sheet'!BH12) -> 0 | P12: ='Raw Sheet'!BJ12 -> 0 | Q12: ='Raw Sheet'!BD12 -> 0 | R12: =E12+SUM(F12:Q12) -> 129200 | S12: =E12+SUM(M12:Q12) -> 127800 | T12: =SUM(F12:L12) -> 1400 | Z12: =S12-SUM(W12:Y12) -> 127800 | AA12: =IF(Z12>=333333,"333333",IF(Z12>=83333,"83333",IF(Z12>=33333,"33333",IF(Z12>=16667,"16667",IF(Z12>=10417,"10417",IF(Z12<10417,"0")))))) -> 83333 | AB12: =AA12+0 -> 83333 | AC12: =VLOOKUP(AB12,WTAX!E:F,2,0) -> 0.3 | AD12: =VLOOKUP(AB12,WTAX!E:G,3,0) -> 16770.7 | AE12: =(Z12-AB12)*AC12 -> 13340.1 | AF12: =AD12+AE12 -> 30110.8 | AG12: =VLOOKUP(B12,'Raw Sheet'!$B$8:$V$28,21,FALSE) -> 0 | AH12: =VLOOKUP(B12,'Raw Sheet'!$B$8:$W$28,22,FALSE) -> 0 | AI12: =VLOOKUP(B12,'Raw Sheet'!$B$8:$X$28,23,FALSE) -> 0 | AJ12: =VLOOKUP(B12,'Raw Sheet'!$B$8:$Y$28,24,FALSE) -> 41395.83 | AK12: =[1]Carreon!$D$44 -> 0 | AL12: =T12 -> 1400 | AM12: =Z12-SUM(AF12:AJ12)+SUM(AK12:AL12) -> 57693.37 | AN12: 0 | AO12: 0 | AP12: 0 | AQ12: 0 | AR12: 0 | AS12: 0 | AW12: =SUM(AU12:AV12) -> 0 | AX12: =AQ12+W12 -> 0 | AZ12: =SUM(Y12,AS12) -> 0
A13: 15 | B13: 31 | C13: F | D13: =VLOOKUP(B13,'Raw Sheet'!$B$8:$G$28,6,FALSE) -> 26000 | E13: =D13/2 -> 13000 | F13: 0 | G13: =VLOOKUP(B13,'Raw Sheet'!$B$8:$L$28,11,FALSE)/2 -> 780 | H13: =VLOOKUP(B13,'Raw Sheet'!$B$8:$M$28,12,FALSE)/2 -> 0 | I13: =VLOOKUP(B13,'Raw Sheet'!$B$8:$N$28,13,FALSE)/2 -> 0 | J13: 0 | K13: 0 | L13: 0 | M13: 0 | N13: ='Raw Sheet'!AH13+'Raw Sheet'!AL13 -> 0 | O13: =SUM('Raw Sheet'!AJ13,'Raw Sheet'!AP13,'Raw Sheet'!BB13,'Raw Sheet'!BH13) -> 0 | P13: ='Raw Sheet'!BJ13 -> 0 | Q13: ='Raw Sheet'!BD13 -> 1912.6437 | R13: =E13+SUM(F13:Q13) -> 15692.644 | S13: =E13+SUM(M13:Q13) -> 14912.644 | T13: =SUM(F13:L13) -> 780 | Z13: =S13-SUM(W13:Y13) -> 14912.644 | AA13: =IF(Z13>=333333,"333333",IF(Z13>=83333,"83333",IF(Z13>=33333,"33333",IF(Z13>=16667,"16667",IF(Z13>=10417,"10417",IF(Z13<10417,"0")))))) -> 10417 | AB13: =AA13+0 -> 10417 | AC13: =VLOOKUP(AB13,WTAX!E:F,2,0) -> 0.15 | AD13: =VLOOKUP(AB13,WTAX!E:G,3,0) -> 0 | AE13: =(Z13-AB13)*AC13 -> 674.34655 | AF13: =AD13+AE13 -> 674.34655 | AG13: =VLOOKUP(B13,'Raw Sheet'!$B$8:$V$28,21,FALSE) -> 0 | AH13: =VLOOKUP(B13,'Raw Sheet'!$B$8:$W$28,22,FALSE) -> 0 | AI13: =VLOOKUP(B13,'Raw Sheet'!$B$8:$X$28,23,FALSE) -> 0 | AJ13: =VLOOKUP(B13,'Raw Sheet'!$B$8:$Y$28,24,FALSE) -> 0 | AK13: =-[1]Colongan!$D$44 -> 4333.3366 | AL13: =T13 -> 780 | AM13: =Z13-SUM(AF13:AJ13)+SUM(AK13:AL13) -> 19351.634 | AN13: 0 | AO13: 0 | AP13: 0 | AQ13: 0 | AR13: 0 | AS13: 0 | AW13: =SUM(AU13:AV13) -> 0 | AX13: =AQ13+W13 -> 0 | AZ13: =SUM(Y13,AS13) -> 0
A14: 19 | B14: 39 | C14: G | D14: =VLOOKUP(B14,'Raw Sheet'!$B$8:$G$28,6,FALSE) -> 29680 | E14: =D14/2 -> 14840 | F14: 0 | G14: =VLOOKUP(B14,'Raw Sheet'!$B$8:$L$28,11,FALSE)/2 -> 1000 | H14: =VLOOKUP(B14,'Raw Sheet'!$B$8:$M$28,12,FALSE)/2 -> 250 | I14: =VLOOKUP(B14,'Raw Sheet'!$B$8:$N$28,13,FALSE)/2 -> 150 | J14: 0 | K14: 0 | L14: 0 | M14: 0 | N14: ='Raw Sheet'!AH14+'Raw Sheet'!AL14 -> 0 | O14: =SUM('Raw Sheet'!AJ14,'Raw Sheet'!AP14,'Raw Sheet'!BB14,'Raw Sheet'!BH14) -> 187.63218 | P14: ='Raw Sheet'!BJ14 -> 0 | Q14: ='Raw Sheet'!BD14 -> 2183.3563 | R14: =E14+SUM(F14:Q14) -> 18610.989 | S14: =E14+SUM(M14:Q14) -> 17210.989 | T14: =SUM(F14:L14) -> 1400 | Z14: =S14-SUM(W14:Y14) -> 17210.989 | AA14: =IF(Z14>=333333,"333333",IF(Z14>=83333,"83333",IF(Z14>=33333,"33333",IF(Z14>=16667,"16667",IF(Z14>=10417,"10417",IF(Z14<10417,"0")))))) -> 16667 | AB14: =AA14+0 -> 16667 | AC14: =VLOOKUP(AB14,WTAX!E:F,2,0) -> 0.2 | AD14: =VLOOKUP(AB14,WTAX!E:G,3,0) -> 937.5 | AE14: =(Z14-AB14)*AC14 -> 108.7977 | AF14: =AD14+AE14 -> 1046.2977 | AG14: =VLOOKUP(B14,'Raw Sheet'!$B$8:$V$28,21,FALSE) -> 0 | AH14: =VLOOKUP(B14,'Raw Sheet'!$B$8:$W$28,22,FALSE) -> 0 | AI14: =VLOOKUP(B14,'Raw Sheet'!$B$8:$X$28,23,FALSE) -> 0 | AJ14: =VLOOKUP(B14,'Raw Sheet'!$B$8:$Y$28,24,FALSE) -> 0 | AK14: =[1]Labradores!$D$44 -> 0.0049425287 | AL14: =T14 -> 1400 | AM14: =Z14-SUM(AF14:AJ14)+SUM(AK14:AL14) -> 17564.696 | AN14: 0 | AO14: 0 | AP14: 0 | AQ14: 0 | AR14: 0 | AS14: 0 | AW14: =SUM(AU14:AV14) -> 0 | AX14: =AQ14+W14 -> 0 | AZ14: =SUM(Y14,AS14) -> 0
A15: 36 | B15: 73 | C15: H | D15: =VLOOKUP(B15,'Raw Sheet'!$B$8:$G$28,6,FALSE) -> 90100 | E15: =D15/2 -> 45050 | F15: 0 | G15: =VLOOKUP(B15,'Raw Sheet'!$B$8:$L$28,11,FALSE)/2 -> 1000 | H15: =VLOOKUP(B15,'Raw Sheet'!$B$8:$M$28,12,FALSE)/2 -> 250 | I15: =VLOOKUP(B15,'Raw Sheet'!$B$8:$N$28,13,FALSE)/2 -> 150 | J15: 0 | K15: 0 | L15: 0 | M15: 0 | N15: ='Raw Sheet'!AH15+'Raw Sheet'!AL15 -> 0 | O15: =SUM('Raw Sheet'!AJ15,'Raw Sheet'!AP15,'Raw Sheet'!BB15,'Raw Sheet'!BH15) -> 0 | P15: ='Raw Sheet'!BJ15 -> 0 | Q15: ='Raw Sheet'!BD15 -> 0 | R15: =E15+SUM(F15:Q15) -> 46450 | S15: =E15+SUM(M15:Q15) -> 45050 | T15: =SUM(F15:L15) -> 1400 | Z15: =S15-SUM(W15:Y15) -> 45050 | AA15: =IF(Z15>=333333,"333333",IF(Z15>=83333,"83333",IF(Z15>=33333,"33333",IF(Z15>=16667,"16667",IF(Z15>=10417,"10417",IF(Z15<10417,"0")))))) -> 33333 | AB15: =AA15+0 -> 33333 | AC15: =VLOOKUP(AB15,WTAX!E:F,2,0) -> 0.25 | AD15: =VLOOKUP(AB15,WTAX!E:G,3,0) -> 4270.7 | AE15: =(Z15-AB15)*AC15 -> 2929.25 | AF15: =AD15+AE15 -> 7199.95 | AG15: =VLOOKUP(B15,'Raw Sheet'!$B$8:$V$28,21,FALSE) -> 0 | AH15: =VLOOKUP(B15,'Raw Sheet'!$B$8:$W$28,22,FALSE) -> 0 | AI15: =VLOOKUP(B15,'Raw Sheet'!$B$8:$X$28,23,FALSE) -> 0 | AJ15: =VLOOKUP(B15,'Raw Sheet'!$B$8:$Y$28,24,FALSE) -> 0 | AK15: =[1]Penaranda!$D$44 -> 0 | AL15: =T15 -> 1400 | AM15: =Z15-SUM(AF15:AJ15)+SUM(AK15:AL15) -> 39250.05 | AN15: 0 | AO15: 0 | AP15: 0 | AQ15: 0 | AR15: 0 | AS15: 0 | AW15: =SUM(AU15:AV15) -> 0 | AX15: =AQ15+W15 -> 0 | AZ15: =SUM(Y15,AS15) -> 0
A16: 37 | B16: 75 | C16: I | D16: =VLOOKUP(B16,'Raw Sheet'!$B$8:$G$28,6,FALSE) -> 133125 | E16: =D16/2 -> 66562.5 | F16: 0 | G16: =VLOOKUP(B16,'Raw Sheet'!$B$8:$L$28,11,FALSE)/2 -> 1000 | H16: =VLOOKUP(B16,'Raw Sheet'!$B$8:$M$28,12,FALSE)/2 -> 250 | I16: =VLOOKUP(B16,'Raw Sheet'!$B$8:$N$28,13,FALSE)/2 -> 150 | J16: 0 | K16: 0 | L16: 0 | M16: 0 | N16: ='Raw Sheet'!AH16+'Raw Sheet'!AL16 -> 0 | O16: =SUM('Raw Sheet'!AJ16,'Raw Sheet'!AP16,'Raw Sheet'!BB16,'Raw Sheet'!BH16) -> 3060.3448 | P16: ='Raw Sheet'!BJ16 -> 0 | Q16: ='Raw Sheet'!BD16 -> 0 | R16: =E16+SUM(F16:Q16) -> 71022.845 | S16: =E16+SUM(M16:Q16) -> 69622.845 | T16: =SUM(F16:L16) -> 1400 | Z16: =S16-SUM(W16:Y16) -> 69622.845 | AA16: =IF(Z16>=333333,"333333",IF(Z16>=83333,"83333",IF(Z16>=33333,"33333",IF(Z16>=16667,"16667",IF(Z16>=10417,"10417",IF(Z16<10417,"0")))))) -> 33333 | AB16: =AA16+0 -> 33333 | AC16: =VLOOKUP(AB16,WTAX!E:F,2,0) -> 0.25 | AD16: =VLOOKUP(AB16,WTAX!E:G,3,0) -> 4270.7 | AE16: =(Z16-AB16)*AC16 -> 9072.4612 | AF16: =AD16+AE16 -> 13343.161 | AG16: =VLOOKUP(B16,'Raw Sheet'!$B$8:$V$28,21,FALSE) -> 0 | AH16: =VLOOKUP(B16,'Raw Sheet'!$B$8:$W$28,22,FALSE) -> 0 | AI16: =VLOOKUP(B16,'Raw Sheet'!$B$8:$X$28,23,FALSE) -> 0 | AJ16: =VLOOKUP(B16,'Raw Sheet'!$B$8:$Y$28,24,FALSE) -> 0 | AK16: =[1]Cabante!$D$44 -> 0.0042816091 | AL16: =T16 -> 1400 | AM16: =Z16-SUM(AF16:AJ16)+SUM(AK16:AL16) -> 57679.688 | AN16: 0 | AO16: 0 | AP16: 0 | AQ16: 0 | AR16: 0 | AS16: 0 | AW16: =SUM(AU16:AV16) -> 0 | AX16: =AQ16+W16 -> 0 | AZ16: =SUM(Y16,AS16) -> 0
A17: 39 | B17: 79 | C17: J | D17: =VLOOKUP(B17,'Raw Sheet'!$B$8:$G$28,6,FALSE) -> 26250 | E17: =D17/2 -> 13125 | F17: 0 | G17: =VLOOKUP(B17,'Raw Sheet'!$B$8:$L$28,11,FALSE)/2 -> 1000 | H17: =VLOOKUP(B17,'Raw Sheet'!$B$8:$M$28,12,FALSE)/2 -> 250 | I17: =VLOOKUP(B17,'Raw Sheet'!$B$8:$N$28,13,FALSE)/2 -> 150 | J17: 0 | K17: 0 | L17: 0 | M17: 0 | N17: ='Raw Sheet'!AH17+'Raw Sheet'!AL17 -> 3439.6552 | O17: =SUM('Raw Sheet'!AJ17,'Raw Sheet'!AP17,'Raw Sheet'!BB17,'Raw Sheet'!BH17) -> 1297.4138 | P17: ='Raw Sheet'!BJ17 -> 0 | Q17: ='Raw Sheet'!BD17 -> 0 | R17: =E17+SUM(F17:Q17) -> 19262.069 | S17: =E17+SUM(M17:Q17) -> 17862.069 | T17: =SUM(F17:L17) -> 1400 | Z17: =S17-SUM(W17:Y17) -> 17862.069 | AA17: =IF(Z17>=333333,"333333",IF(Z17>=83333,"83333",IF(Z17>=33333,"33333",IF(Z17>=16667,"16667",IF(Z17>=10417,"10417",IF(Z17<10417,"0")))))) -> 16667 | AB17: =AA17+0 -> 16667 | AC17: =VLOOKUP(AB17,WTAX!E:F,2,0) -> 0.2 | AD17: =VLOOKUP(AB17,WTAX!E:G,3,0) -> 937.5 | AE17: =(Z17-AB17)*AC17 -> 239.01379 | AF17: =AD17+AE17 -> 1176.5138 | AG17: =VLOOKUP(B17,'Raw Sheet'!$B$8:$V$28,21,FALSE) -> 0 | AH17: =VLOOKUP(B17,'Raw Sheet'!$B$8:$W$28,22,FALSE) -> 0 | AI17: =VLOOKUP(B17,'Raw Sheet'!$B$8:$X$28,23,FALSE) -> 0 | AJ17: =VLOOKUP(B17,'Raw Sheet'!$B$8:$Y$28,24,FALSE) -> 0 | AK17: =[1]Zamora!$D$44 -> -0.0022413793 | AL17: =T17 -> 1400 | AM17: =Z17-SUM(AF17:AJ17)+SUM(AK17:AL17) -> 18085.553 | AN17: 0 | AO17: 0 | AP17: 0 | AQ17: 0 | AR17: 0 | AS17: 0 | AW17: =SUM(AU17:AV17) -> 0 | AX17: =AQ17+W17 -> 0 | AZ17: =SUM(Y17,AS17) -> 0
A18: 41 | B18: 83 | C18: K | D18: =VLOOKUP(B18,'Raw Sheet'!$B$8:$G$28,6,FALSE) -> 28646 | E18: =D18/2 -> 14323 | F18: 0 | G18: =VLOOKUP(B18,'Raw Sheet'!$B$8:$L$28,11,FALSE)/2 -> 1000 | H18: =VLOOKUP(B18,'Raw Sheet'!$B$8:$M$28,12,FALSE)/2 -> 250 | I18: =VLOOKUP(B18,'Raw Sheet'!$B$8:$N$28,13,FALSE)/2 -> 150 | J18: 0 | K18: 0 | L18: 0 | M18: 0 | N18: ='Raw Sheet'!AH18+'Raw Sheet'!AL18 -> 0 | O18: =SUM('Raw Sheet'!AJ18,'Raw Sheet'!AP18,'Raw Sheet'!BB18,'Raw Sheet'!BH18) -> 1317.0575 | P18: ='Raw Sheet'!BJ18 -> 0 | Q18: ='Raw Sheet'!BD18 -> 329.26437 | R18: =E18+SUM(F18:Q18) -> 17369.322 | S18: =E18+SUM(M18:Q18) -> 15969.322 | T18: =SUM(F18:L18) -> 1400 | Z18: =S18-SUM(W18:Y18) -> 15969.322 | AA18: =IF(Z18>=333333,"333333",IF(Z18>=83333,"83333",IF(Z18>=33333,"33333",IF(Z18>=16667,"16667",IF(Z18>=10417,"10417",IF(Z18<10417,"0")))))) -> 10417 | AB18: =AA18+0 -> 10417 | AC18: =VLOOKUP(AB18,WTAX!E:F,2,0) -> 0.15 | AD18: =VLOOKUP(AB18,WTAX!E:G,3,0) -> 0 | AE18: =(Z18-AB18)*AC18 -> 832.84828 | AF18: =AD18+AE18 -> 832.84828 | AG18: =VLOOKUP(B18,'Raw Sheet'!$B$8:$V$28,21,FALSE) -> 0 | AH18: =VLOOKUP(B18,'Raw Sheet'!$B$8:$W$28,22,FALSE) -> 0 | AI18: =VLOOKUP(B18,'Raw Sheet'!$B$8:$X$28,23,FALSE) -> 0 | AJ18: =VLOOKUP(B18,'Raw Sheet'!$B$8:$Y$28,24,FALSE) -> 0 | AK18: =[1]Belarma!$D$44 -> 0.0015517241 | AL18: =T18 -> 1400 | AM18: =Z18-SUM(AF18:AJ18)+SUM(AK18:AL18) -> 16536.475 | AN18: 0 | AO18: 0 | AP18: 0 | AQ18: 0 | AR18: 0 | AS18: 0 | AW18: =SUM(AU18:AV18) -> 0 | AX18: =AQ18+W18 -> 0 | AZ18: =SUM(Y18,AS18) -> 0
A19: 42 | B19: 85 | C19: L | D19: =VLOOKUP(B19,'Raw Sheet'!$B$8:$G$28,6,FALSE) -> 187500 | E19: =D19/2 -> 93750 | F19: 0 | G19: =VLOOKUP(B19,'Raw Sheet'!$B$8:$L$28,11,FALSE)/2 -> 1000 | H19: =VLOOKUP(B19,'Raw Sheet'!$B$8:$M$28,12,FALSE)/2 -> 250 | I19: =VLOOKUP(B19,'Raw Sheet'!$B$8:$N$28,13,FALSE)/2 -> 150 | J19: 0 | K19: 0 | L19: 0 | M19: 0 | N19: ='Raw Sheet'!AH19+'Raw Sheet'!AL19 -> 0 | O19: =SUM('Raw Sheet'!AJ19,'Raw Sheet'!AP19,'Raw Sheet'!BB19,'Raw Sheet'!BH19) -> 2155.1724 | P19: ='Raw Sheet'!BJ19 -> 0 | Q19: ='Raw Sheet'!BD19 -> 0 | R19: =E19+SUM(F19:Q19) -> 97305.172 | S19: =E19+SUM(M19:Q19) -> 95905.172 | T19: =SUM(F19:L19) -> 1400 | Z19: =S19-SUM(W19:Y19) -> 95905.172 | AA19: =IF(Z19>=333333,"333333",IF(Z19>=83333,"83333",IF(Z19>=33333,"33333",IF(Z19>=16667,"16667",IF(Z19>=10417,"10417",IF(Z19<10417,"0")))))) -> 83333 | AB19: =AA19+0 -> 83333 | AC19: =VLOOKUP(AB19,WTAX!E:F,2,0) -> 0.3 | AD19: =VLOOKUP(AB19,WTAX!E:G,3,0) -> 16770.7 | AE19: =(Z19-AB19)*AC19 -> 3771.6517 | AF19: =AD19+AE19 -> 20542.352 | AG19: =VLOOKUP(B19,'Raw Sheet'!$B$8:$V$28,21,FALSE) -> 0 | AH19: =VLOOKUP(B19,'Raw Sheet'!$B$8:$W$28,22,FALSE) -> 0 | AI19: =VLOOKUP(B19,'Raw Sheet'!$B$8:$X$28,23,FALSE) -> 0 | AJ19: =VLOOKUP(B19,'Raw Sheet'!$B$8:$Y$28,24,FALSE) -> 0 | AK19: =[1]Virtudes!$D$44 -> 0 | AL19: =T19 -> 1400 | AM19: =Z19-SUM(AF19:AJ19)+SUM(AK19:AL19) -> 76762.821 | AN19: 0 | AO19: 0 | AP19: 0 | AQ19: 0 | AR19: 0 | AS19: 0 | AW19: =SUM(AU19:AV19) -> 0 | AX19: =AQ19+W19 -> 0 | AZ19: =SUM(Y19,AS19) -> 0
A20: 43 | B20: 87 | C20: M | D20: =VLOOKUP(B20,'Raw Sheet'!$B$8:$G$28,6,FALSE) -> 102816 | E20: =D20/2 -> 51408 | F20: 0 | G20: =VLOOKUP(B20,'Raw Sheet'!$B$8:$L$28,11,FALSE)/2 -> 1000 | H20: =VLOOKUP(B20,'Raw Sheet'!$B$8:$M$28,12,FALSE)/2 -> 250 | I20: =VLOOKUP(B20,'Raw Sheet'!$B$8:$N$28,13,FALSE)/2 -> 150 | J20: 0 | K20: 0 | L20: 0 | M20: 0 | N20: ='Raw Sheet'!AH20+'Raw Sheet'!AL20 -> 0 | O20: =SUM('Raw Sheet'!AJ20,'Raw Sheet'!AP20,'Raw Sheet'!BB20,'Raw Sheet'!BH20) -> 0 | P20: ='Raw Sheet'!BJ20 -> -14181.517 | Q20: ='Raw Sheet'!BD20 -> 0 | R20: =E20+SUM(F20:Q20) -> 38626.483 | S20: =E20+SUM(M20:Q20) -> 37226.483 | T20: =SUM(F20:L20) -> 1400 | Z20: =S20-SUM(W20:Y20) -> 37226.483 | AA20: =IF(Z20>=333333,"333333",IF(Z20>=83333,"83333",IF(Z20>=33333,"33333",IF(Z20>=16667,"16667",IF(Z20>=10417,"10417",IF(Z20<10417,"0")))))) -> 33333 | AB20: =AA20+0 -> 33333 | AC20: =VLOOKUP(AB20,WTAX!E:F,2,0) -> 0.25 | AD20: =VLOOKUP(AB20,WTAX!E:G,3,0) -> 4270.7 | AE20: =(Z20-AB20)*AC20 -> 973.37069 | AF20: =AD20+AE20 -> 5244.0707 | AG20: =VLOOKUP(B20,'Raw Sheet'!$B$8:$V$28,21,FALSE) -> 0 | AH20: =VLOOKUP(B20,'Raw Sheet'!$B$8:$W$28,22,FALSE) -> 0 | AI20: =VLOOKUP(B20,'Raw Sheet'!$B$8:$X$28,23,FALSE) -> 0 | AJ20: =VLOOKUP(B20,'Raw Sheet'!$B$8:$Y$28,24,FALSE) -> 0 | AK20: =[1]Bautista!$D$44 -> -0.0022988507 | AL20: =T20 -> 1400 | AM20: =Z20-SUM(AF20:AJ20)+SUM(AK20:AL20) -> 33382.41 | AN20: 0 | AO20: 0 | AP20: 0 | AQ20: 0 | AR20: 0 | AS20: 0 | AW20: =SUM(AU20:AV20) -> 0 | AX20: =AQ20+W20 -> 0 | AZ20: =SUM(Y20,AS20) -> 0
A21: 44 | B21: 89 | C21: N | D21: =VLOOKUP(B21,'Raw Sheet'!$B$8:$G$28,6,FALSE) -> 24700 | E21: =D21/2 -> 12350 | F21: 0 | G21: =VLOOKUP(B21,'Raw Sheet'!$B$8:$L$28,11,FALSE)/2 -> 1000 | H21: =VLOOKUP(B21,'Raw Sheet'!$B$8:$M$28,12,FALSE)/2 -> 250 | I21: =VLOOKUP(B21,'Raw Sheet'!$B$8:$N$28,13,FALSE)/2 -> 150 | J21: 0 | K21: 0 | L21: 0 | M21: 0 | N21: ='Raw Sheet'!AH21+'Raw Sheet'!AL21 -> 0 | O21: =SUM('Raw Sheet'!AJ21,'Raw Sheet'!AP21,'Raw Sheet'!BB21,'Raw Sheet'!BH21) -> 908.50575 | P21: ='Raw Sheet'!BJ21 -> 0 | Q21: ='Raw Sheet'!BD21 -> 425.86207 | R21: =E21+SUM(F21:Q21) -> 15084.368 | S21: =E21+SUM(M21:Q21) -> 13684.368 | T21: =SUM(F21:L21) -> 1400 | Z21: =S21-SUM(W21:Y21) -> 13684.368 | AA21: =IF(Z21>=333333,"333333",IF(Z21>=83333,"83333",IF(Z21>=33333,"33333",IF(Z21>=16667,"16667",IF(Z21>=10417,"10417",IF(Z21<10417,"0")))))) -> 10417 | AB21: =AA21+0 -> 10417 | AC21: =VLOOKUP(AB21,WTAX!E:F,2,0) -> 0.15 | AD21: =VLOOKUP(AB21,WTAX!E:G,3,0) -> 0 | AE21: =(Z21-AB21)*AC21 -> 490.10517 | AF21: =AD21+AE21 -> 490.10517 | AG21: =VLOOKUP(B21,'Raw Sheet'!$B$8:$V$28,21,FALSE) -> 697.88 | AH21: =VLOOKUP(B21,'Raw Sheet'!$B$8:$W$28,22,FALSE) -> 0 | AI21: =VLOOKUP(B21,'Raw Sheet'!$B$8:$X$28,23,FALSE) -> 697.88 | AJ21: =VLOOKUP(B21,'Raw Sheet'!$B$8:$Y$28,24,FALSE) -> 0 | AK21: =[1]Angeles!$D$44 -> -0.00068965518 | AL21: =T21 -> 1400 | AM21: =Z21-SUM(AF21:AJ21)+SUM(AK21:AL21) -> 13198.502 | AN21: 0 | AO21: 0 | AP21: 0 | AQ21: 0 | AR21: 0 | AS21: 0 | AW21: =SUM(AU21:AV21) -> 0 | AX21: =AQ21+W21 -> 0 | AZ21: =SUM(Y21,AS21) -> 0
A22: 45 | B22: 91 | C22: O | D22: =VLOOKUP(B22,'Raw Sheet'!$B$8:$G$28,6,FALSE) -> 85000 | E22: =D22/2 -> 42500 | F22: 0 | G22: =VLOOKUP(B22,'Raw Sheet'!$B$8:$L$28,11,FALSE)/2 -> 1000 | H22: =VLOOKUP(B22,'Raw Sheet'!$B$8:$M$28,12,FALSE)/2 -> 250 | I22: =VLOOKUP(B22,'Raw Sheet'!$B$8:$N$28,13,FALSE)/2 -> 150 | J22: 0 | K22: 0 | L22: 0 | M22: 0 | N22: ='Raw Sheet'!AH22+'Raw Sheet'!AL22 -> 7474.1379 | O22: =SUM('Raw Sheet'!AJ22,'Raw Sheet'!AP22,'Raw Sheet'!BB22,'Raw Sheet'!BH22) -> 3517.2414 | P22: ='Raw Sheet'!BJ22 -> 0 | Q22: ='Raw Sheet'!BD22 -> 0 | R22: =E22+SUM(F22:Q22) -> 54891.379 | S22: =E22+SUM(M22:Q22) -> 53491.379 | T22: =SUM(F22:L22) -> 1400 | Z22: =S22-SUM(W22:Y22) -> 53491.379 | AA22: =IF(Z22>=333333,"333333",IF(Z22>=83333,"83333",IF(Z22>=33333,"33333",IF(Z22>=16667,"16667",IF(Z22>=10417,"10417",IF(Z22<10417,"0")))))) -> 33333 | AB22: =AA22+0 -> 33333 | AC22: =VLOOKUP(AB22,WTAX!E:F,2,0) -> 0.25 | AD22: =VLOOKUP(AB22,WTAX!E:G,3,0) -> 4270.7 | AE22: =(Z22-AB22)*AC22 -> 5039.5948 | AF22: =AD22+AE22 -> 9310.2948 | AG22: =VLOOKUP(B22,'Raw Sheet'!$B$8:$V$28,21,FALSE) -> 0 | AH22: =VLOOKUP(B22,'Raw Sheet'!$B$8:$W$28,22,FALSE) -> 0 | AI22: =VLOOKUP(B22,'Raw Sheet'!$B$8:$X$28,23,FALSE) -> 0 | AJ22: =VLOOKUP(B22,'Raw Sheet'!$B$8:$Y$28,24,FALSE) -> 0 | AK22: =[1]Morante!$D$44 -> 0.00022988504 | AL22: =T22 -> 1400 | AM22: =Z22-SUM(AF22:AJ22)+SUM(AK22:AL22) -> 45581.085 | AN22: 0 | AO22: 0 | AP22: 0 | AQ22: 0 | AR22: 0 | AS22: 0 | AW22: =SUM(AU22:AV22) -> 0 | AX22: =AQ22+W22 -> 0 | AZ22: =SUM(Y22,AS22) -> 0
A23: 46 | B23: 93 | C23: P | D23: =VLOOKUP(B23,'Raw Sheet'!$B$8:$G$28,6,FALSE) -> 130000 | E23: =D23/2 -> 65000 | F23: 0 | G23: =VLOOKUP(B23,'Raw Sheet'!$B$8:$L$28,11,FALSE)/2 -> 1000 | H23: =VLOOKUP(B23,'Raw Sheet'!$B$8:$M$28,12,FALSE)/2 -> 250 | I23: =VLOOKUP(B23,'Raw Sheet'!$B$8:$N$28,13,FALSE)/2 -> 150 | J23: 0 | K23: 0 | L23: 0 | M23: 0 | N23: ='Raw Sheet'!AH23+'Raw Sheet'!AL23 -> 5715.5172 | O23: =SUM('Raw Sheet'!AJ23,'Raw Sheet'!AP23,'Raw Sheet'!BB23,'Raw Sheet'!BH23) -> 3586.2069 | P23: ='Raw Sheet'!BJ23 -> 0 | Q23: ='Raw Sheet'!BD23 -> 0 | R23: =E23+SUM(F23:Q23) -> 75701.724 | S23: =E23+SUM(M23:Q23) -> 74301.724 | T23: =SUM(F23:L23) -> 1400 | Z23: =S23-SUM(W23:Y23) -> 74301.724 | AA23: =IF(Z23>=333333,"333333",IF(Z23>=83333,"83333",IF(Z23>=33333,"33333",IF(Z23>=16667,"16667",IF(Z23>=10417,"10417",IF(Z23<10417,"0")))))) -> 33333 | AB23: =AA23+0 -> 33333 | AC23: =VLOOKUP(AB23,WTAX!E:F,2,0) -> 0.25 | AD23: =VLOOKUP(AB23,WTAX!E:G,3,0) -> 4270.7 | AE23: =(Z23-AB23)*AC23 -> 10242.181 | AF23: =AD23+AE23 -> 14512.881 | AG23: =VLOOKUP(B23,'Raw Sheet'!$B$8:$V$28,21,FALSE) -> 1845.8 | AH23: =VLOOKUP(B23,'Raw Sheet'!$B$8:$W$28,22,FALSE) -> 0 | AI23: =VLOOKUP(B23,'Raw Sheet'!$B$8:$X$28,23,FALSE) -> 0 | AJ23: =VLOOKUP(B23,'Raw Sheet'!$B$8:$Y$28,24,FALSE) -> 0 | AK23: =-[1]Lindo!$D$44 -> -9750.9512 | AL23: =T23 -> 1400 | AM23: =Z23-SUM(AF23:AJ23)+SUM(AK23:AL23) -> 49592.092 | AN23: 0 | AO23: 0 | AP23: 0 | AQ23: 0 | AR23: 0 | AS23: 0 | AW23: =SUM(AU23:AV23) -> 0 | AX23: =AQ23+W23 -> 0 | AZ23: =SUM(Y23,AS23) -> 0
A24: 47 | B24: 95 | C24: Q | D24: =VLOOKUP(B24,'Raw Sheet'!$B$8:$G$28,6,FALSE) -> 30000 | E24: =D24/2 -> 15000 | F24: 0 | G24: =VLOOKUP(B24,'Raw Sheet'!$B$8:$L$28,11,FALSE)/2 -> 1000 | H24: =VLOOKUP(B24,'Raw Sheet'!$B$8:$M$28,12,FALSE)/2 -> 250 | I24: =VLOOKUP(B24,'Raw Sheet'!$B$8:$N$28,13,FALSE)/2 -> 150 | J24: 0 | K24: 0 | L24: 0 | M24: 0 | N24: ='Raw Sheet'!AH24+'Raw Sheet'!AL24 -> 0 | O24: =SUM('Raw Sheet'!AJ24,'Raw Sheet'!AP24,'Raw Sheet'!BB24,'Raw Sheet'!BH24) -> 275.86207 | P24: ='Raw Sheet'!BJ24 -> -1379.3103 | Q24: ='Raw Sheet'!BD24 -> 1379.3103 | R24: =E24+SUM(F24:Q24) -> 16675.862 | S24: =E24+SUM(M24:Q24) -> 15275.862 | T24: =SUM(F24:L24) -> 1400 | Z24: =S24-SUM(W24:Y24) -> 15275.862 | AA24: =IF(Z24>=333333,"333333",IF(Z24>=83333,"83333",IF(Z24>=33333,"33333",IF(Z24>=16667,"16667",IF(Z24>=10417,"10417",IF(Z24<10417,"0")))))) -> 10417 | AB24: =AA24+0 -> 10417 | AC24: =VLOOKUP(AB24,WTAX!E:F,2,0) -> 0.15 | AD24: =VLOOKUP(AB24,WTAX!E:G,3,0) -> 0 | AE24: =(Z24-AB24)*AC24 -> 728.82931 | AF24: =AD24+AE24 -> 728.82931 | AG24: =VLOOKUP(B24,'Raw Sheet'!$B$8:$V$28,21,FALSE) -> 0 | AH24: =VLOOKUP(B24,'Raw Sheet'!$B$8:$W$28,22,FALSE) -> 0 | AI24: =VLOOKUP(B24,'Raw Sheet'!$B$8:$X$28,23,FALSE) -> 0 | AJ24: =VLOOKUP(B24,'Raw Sheet'!$B$8:$Y$28,24,FALSE) -> 0 | AK24: =[1]Silva!$D$44 -> -0.0035862069 | AL24: =T24 -> 1400 | AM24: =Z24-SUM(AF24:AJ24)+SUM(AK24:AL24) -> 15947.029 | AN24: 0 | AO24: 0 | AP24: 0 | AQ24: 0 | AR24: 0 | AS24: 0 | AW24: =SUM(AU24:AV24) -> 0 | AX24: =AQ24+W24 -> 0 | AZ24: =SUM(Y24,AS24) -> 0
A25: 49 | B25: 99 | C25: R | D25: =VLOOKUP(B25,'Raw Sheet'!$B$8:$G$28,6,FALSE) -> 28000 | E25: =D25/2 -> 14000 | F25: 0 | G25: =VLOOKUP(B25,'Raw Sheet'!$B$8:$L$28,11,FALSE)/2 -> 1000 | H25: =VLOOKUP(B25,'Raw Sheet'!$B$8:$M$28,12,FALSE)/2 -> 250 | I25: =VLOOKUP(B25,'Raw Sheet'!$B$8:$N$28,13,FALSE)/2 -> 150 | J25: 0 | K25: 0 | L25: 0 | M25: 0 | N25: ='Raw Sheet'!AH25+'Raw Sheet'!AL25 -> 0 | O25: =SUM('Raw Sheet'!AJ25,'Raw Sheet'!AP25,'Raw Sheet'!BB25,'Raw Sheet'!BH25) -> 321.83908 | P25: ='Raw Sheet'!BJ25 -> 0 | Q25: ='Raw Sheet'!BD25 -> 0 | R25: =E25+SUM(F25:Q25) -> 15721.839 | S25: =E25+SUM(M25:Q25) -> 14321.839 | T25: =SUM(F25:L25) -> 1400 | Z25: =S25-SUM(W25:Y25) -> 14321.839 | AA25: =IF(Z25>=333333,"333333",IF(Z25>=83333,"83333",IF(Z25>=33333,"33333",IF(Z25>=16667,"16667",IF(Z25>=10417,"10417",IF(Z25<10417,"0")))))) -> 10417 | AB25: =AA25+0 -> 10417 | AC25: =VLOOKUP(AB25,WTAX!E:F,2,0) -> 0.15 | AD25: =VLOOKUP(AB25,WTAX!E:G,3,0) -> 0 | AE25: =(Z25-AB25)*AC25 -> 585.72586 | AF25: =AD25+AE25 -> 585.72586 | AG25: =VLOOKUP(B25,'Raw Sheet'!$B$8:$V$28,21,FALSE) -> 0 | AH25: =VLOOKUP(B25,'Raw Sheet'!$B$8:$W$28,22,FALSE) -> 0 | AI25: =VLOOKUP(B25,'Raw Sheet'!$B$8:$X$28,23,FALSE) -> 0 | AJ25: =VLOOKUP(B25,'Raw Sheet'!$B$8:$Y$28,24,FALSE) -> 0 | AK25: =[1]Espino!$D$44 -> -0.00022988506 | AL25: =T25 -> 1400 | AM25: =Z25-SUM(AF25:AJ25)+SUM(AK25:AL25) -> 15136.113 | AN25: 0 | AO25: 0 | AP25: 0 | AQ25: 0 | AR25: 0 | AS25: 0 | AW25: =SUM(AU25:AV25) -> 0 | AX25: =AQ25+W25 -> 0 | AZ25: =SUM(Y25,AS25) -> 0
A26: 50 | B26: 101 | C26: S | D26: =VLOOKUP(B26,'Raw Sheet'!$B$8:$G$28,6,FALSE) -> 85000 | E26: =D26/2 -> 42500 | F26: 0 | G26: =VLOOKUP(B26,'Raw Sheet'!$B$8:$L$28,11,FALSE)/2 -> 1000 | H26: =VLOOKUP(B26,'Raw Sheet'!$B$8:$M$28,12,FALSE)/2 -> 250 | I26: =VLOOKUP(B26,'Raw Sheet'!$B$8:$N$28,13,FALSE)/2 -> 150 | J26: 0 | K26: 0 | L26: 0 | M26: 0 | N26: ='Raw Sheet'!AH26+'Raw Sheet'!AL26 -> 3737.069 | O26: =SUM('Raw Sheet'!AJ26,'Raw Sheet'!AP26,'Raw Sheet'!BB26,'Raw Sheet'!BH26) -> 1563.2184 | P26: ='Raw Sheet'!BJ26 -> 0 | Q26: ='Raw Sheet'!BD26 -> 0 | R26: =E26+SUM(F26:Q26) -> 49200.287 | S26: =E26+SUM(M26:Q26) -> 47800.287 | T26: =SUM(F26:L26) -> 1400 | Z26: =S26-SUM(W26:Y26) -> 47800.287 | AA26: =IF(Z26>=333333,"333333",IF(Z26>=83333,"83333",IF(Z26>=33333,"33333",IF(Z26>=16667,"16667",IF(Z26>=10417,"10417",IF(Z26<10417,"0")))))) -> 33333 | AB26: =AA26+0 -> 33333 | AC26: =VLOOKUP(AB26,WTAX!E:F,2,0) -> 0.25 | AD26: =VLOOKUP(AB26,WTAX!E:G,3,0) -> 4270.7 | AE26: =(Z26-AB26)*AC26 -> 3616.8218 | AF26: =AD26+AE26 -> 7887.5218 | AG26: =VLOOKUP(B26,'Raw Sheet'!$B$8:$V$28,21,FALSE) -> 1809.09 | AH26: =VLOOKUP(B26,'Raw Sheet'!$B$8:$W$28,22,FALSE) -> 0 | AI26: =VLOOKUP(B26,'Raw Sheet'!$B$8:$X$28,23,FALSE) -> 0 | AJ26: =VLOOKUP(B26,'Raw Sheet'!$B$8:$Y$28,24,FALSE) -> 0 | AK26: =[1]Austria!$D$44 -> -0.0017471265 | AL26: =T26 -> 1400 | AM26: =Z26-SUM(AF26:AJ26)+SUM(AK26:AL26) -> 39503.674 | AN26: 0 | AO26: 0 | AP26: 0 | AQ26: 0 | AR26: 0 | AS26: 0 | AW26: =SUM(AU26:AV26) -> 0 | AX26: =AQ26+W26 -> 0 | AZ26: =SUM(Y26,AS26) -> 0
A27: 51 | B27: 103 | C27: T | D27: =VLOOKUP(B27,'Raw Sheet'!$B$8:$G$28,6,FALSE) -> 22000 | E27: =D27/2 -> 11000 | F27: 0 | G27: =VLOOKUP(B27,'Raw Sheet'!$B$8:$L$28,11,FALSE)/2 -> 1000 | H27: =VLOOKUP(B27,'Raw Sheet'!$B$8:$M$28,12,FALSE)/2 -> 250 | I27: =VLOOKUP(B27,'Raw Sheet'!$B$8:$N$28,13,FALSE)/2 -> 150 | J27: 0 | K27: 0 | L27: 0 | M27: 0 | N27: ='Raw Sheet'!AH27+'Raw Sheet'!AL27 -> 0 | O27: =SUM('Raw Sheet'!AJ27,'Raw Sheet'!AP27,'Raw Sheet'!BB27,'Raw Sheet'!BH27) -> 303.44828 | P27: ='Raw Sheet'!BJ27 -> -252.87356 | Q27: ='Raw Sheet'!BD27 -> 1011.4943 | R27: =E27+SUM(F27:Q27) -> 13462.069 | S27: =E27+SUM(M27:Q27) -> 12062.069 | T27: =SUM(F27:L27) -> 1400 | Z27: =S27-SUM(W27:Y27) -> 12062.069 | AA27: =IF(Z27>=333333,"333333",IF(Z27>=83333,"83333",IF(Z27>=33333,"33333",IF(Z27>=16667,"16667",IF(Z27>=10417,"10417",IF(Z27<10417,"0")))))) -> 10417 | AB27: =AA27+0 -> 10417 | AC27: =VLOOKUP(AB27,WTAX!E:F,2,0) -> 0.15 | AD27: =VLOOKUP(AB27,WTAX!E:G,3,0) -> 0 | AE27: =(Z27-AB27)*AC27 -> 246.76034 | AF27: =AD27+AE27 -> 246.76034 | AG27: =VLOOKUP(B27,'Raw Sheet'!$B$8:$V$28,21,FALSE) -> 0 | AH27: =VLOOKUP(B27,'Raw Sheet'!$B$8:$W$28,22,FALSE) -> 0 | AI27: =VLOOKUP(B27,'Raw Sheet'!$B$8:$X$28,23,FALSE) -> 0 | AJ27: =VLOOKUP(B27,'Raw Sheet'!$B$8:$Y$28,24,FALSE) -> 0 | AK27: =[1]Cruz!$D$44 -> 0.0028965517 | AL27: =T27 -> 1400 | AM27: =Z27-SUM(AF27:AJ27)+SUM(AK27:AL27) -> 13215.312 | AN27: 0 | AO27: 0 | AP27: 0 | AQ27: 0 | AR27: 0 | AS27: 0 | AW27: =SUM(AU27:AV27) -> 0 | AX27: =AQ27+W27 -> 0 | AZ27: =SUM(Y27,AS27) -> 0
A28: 52 | B28: 105 | C28: U | D28: =VLOOKUP(B28,'Raw Sheet'!$B$8:$G$28,6,FALSE) -> 18000 | E28: =D28/2 -> 9000 | F28: 0 | G28: =VLOOKUP(B28,'Raw Sheet'!$B$8:$L$28,11,FALSE)/2 -> 1000 | H28: =VLOOKUP(B28,'Raw Sheet'!$B$8:$M$28,12,FALSE)/2 -> 250 | I28: =VLOOKUP(B28,'Raw Sheet'!$B$8:$N$28,13,FALSE)/2 -> 150 | J28: 0 | K28: 0 | L28: 0 | M28: 0 | N28: ='Raw Sheet'!AH28+'Raw Sheet'!AL28 -> 0 | O28: =SUM('Raw Sheet'!AJ28,'Raw Sheet'!AP28,'Raw Sheet'!BB28,'Raw Sheet'!BH28) -> 227.58621 | P28: ='Raw Sheet'!BJ28 -> 0 | Q28: ='Raw Sheet'!BD28 -> 827.58621 | R28: =E28+SUM(F28:Q28) -> 11455.172 | S28: =E28+SUM(M28:Q28) -> 10055.172 | T28: =SUM(F28:L28) -> 1400 | Z28: =S28-SUM(W28:Y28) -> 10055.172 | AA28: =IF(Z28>=333333,"333333",IF(Z28>=83333,"83333",IF(Z28>=33333,"33333",IF(Z28>=16667,"16667",IF(Z28>=10417,"10417",IF(Z28<10417,"0")))))) -> 0 | AB28: =AA28+0 -> 0 | AC28: =VLOOKUP(AB28,WTAX!E:F,2,0) -> 0 | AD28: =VLOOKUP(AB28,WTAX!E:G,3,0) -> 0 | AE28: =(Z28-AB28)*AC28 -> 0 | AF28: =AD28+AE28 -> 0 | AG28: =VLOOKUP(B28,'Raw Sheet'!$B$8:$V$28,21,FALSE) -> 0 | AH28: =VLOOKUP(B28,'Raw Sheet'!$B$8:$W$28,22,FALSE) -> 0 | AI28: =VLOOKUP(B28,'Raw Sheet'!$B$8:$X$28,23,FALSE) -> 0 | AJ28: =VLOOKUP(B28,'Raw Sheet'!$B$8:$Y$28,24,FALSE) -> 0 | AK28: =[1]Magnaye!$D$44 -> 0 | AL28: =T28 -> 1400 | AM28: =Z28-SUM(AF28:AJ28)+SUM(AK28:AL28) -> 11455.172 | AN28: 0 | AO28: 0 | AP28: 0 | AQ28: 0 | AR28: 0 | AS28: 0 | AW28: =SUM(AU28:AV28) -> 0 | AX28: =AQ28+W28 -> 0 | AZ28: =SUM(Y28,AS28) -> 0
C29: TOTAL | D29: =SUM(D8:D28) -> 1596217 | E29: =SUM(E8:E28) -> 798108.5 | F29: =SUM(F8:F28) -> 0 | G29: =SUM(G8:G28) -> 19780 | H29: =SUM(H8:H28) -> 4550 | I29: =SUM(I8:I28) -> 2700 | J29: =SUM(J8:J28) -> 0 | K29: =SUM(K8:K28) -> 0 | ... AB29: =SUM(AB8:AB28) -> 595834 | AD29: =SUM(AD8:AD28) -> 80623.8 | AE29: =SUM(AE8:AE28) -> 57698.758 | AF29: =SUM(AF8:AF28) -> 138322.56 | AG29: =SUM(AG8:AG28) -> 8044.37 | AH29: =SUM(AH8:AH28) -> 0 | AI29: =SUM(AI8:AI28) -> 697.88 | AJ29: =SUM(AJ8:AJ28) -> 41395.83 | AK29: =SUM(AK8:AK28) -> -5417.6122 | ... AS29: =SUM(AS8:AS28) -> 0 | AW29: =SUM(AW8:AW28) -> 0 | AX29: =SUM(AX8:AX28) -> 0 | AY29: =SUM(AY8:AY28) -> 0 | AZ29: =SUM(AZ8:AZ28) -> 0
D31: =D29-'Raw Sheet'!G30 -> 0 | E31: =E29-'Raw Sheet'!H30 -> 0 | G31: =G29-('Raw Sheet'!L30/2) -> 0 | H31: =H29-('Raw Sheet'!M30/2) -> 0 | I31: =I29-('Raw Sheet'!N30/2) -> 0 | N31: =N29-SUM('Raw Sheet'!AH30,'Raw Sheet'!AL30,'Raw Sheet'!AN30) -> 0 | O31: =O29-SUM('Raw Sheet'!AJ30,'Raw Sheet'!AP30,'Raw Sheet'!BB30,'Raw Sheet'!BH30) -> 0 | P31: =P29+'Raw Sheet'!AB30+'Raw Sheet'!AD30 -> 0 | Q31: =Q29-SUM('Raw Sheet'!AX30,'Raw Sheet'!AZ30,'Raw Sheet'!BD30,'Raw Sheet'!BF30) -> 0 | R31: =R29-SUM(E29:Q29) -> 0 | S31: =S29-SUM(E29,M29:Q29) -> 0 | T31: =T29-(('Raw Sheet'!L30+'Raw Sheet'!M30+'Raw Sheet'!N30)/2) -> 0 | Z31: =Z29-SUM(S29,W29:Y29) -> 0 | AF31: =AF29-SUM(AD29:AE29) -> 0 | AG31: =AG29-'Raw Sheet'!V30 -> 0 | AH31: =AH29-'Raw Sheet'!W30 -> 0 | AI31: =AI29-'Raw Sheet'!X30 -> 0 | AJ31: =AJ29-'Raw Sheet'!Y30 -> 0 | AL31: =AL29-(SUM('Raw Sheet'!L30:N30)/2) -> 0 | AM31: =E29+G29+H29+I29+N29+O29+P29+Q29-AF29-AG29-AI29-AJ29+AK29-AM29 -> 0
R32: ='Raw Sheet'!H30+'Raw Sheet'!L30+'Raw Sheet'!M30+'Raw Sheet'!N30+'Raw Sheet'!BI30+'Raw Sheet'!BJ30-(SUM('Raw Sheet'!L30:N30)/2)-R29 -> 0
N34: Payroll Entry:
N35: Salaries Expense | R35: =E29+SUM(M29:Q29) -> 839187.22
N36: De Minimis Benefit | R36: =SUM(F29:K29) -> 27030
N37: Leave Conversion Pay | R37: =L29 -> 0
N38: SSS Contribution | R38: =AQ29 -> 0
N39: Philhealth Contribution | R39: =AR29 -> 0
N40: Pag-ibig Contribution - Direct | R40: =AS29 -> 0
N41: 13th Month Pay & Other Benefits | R41: 0
N42: Advances from Employees | R42: 0
P43: Compensation Withholding Tax | S43: =AF29 -> 138322.56
P44: Advances to Employees | S44: =AJ29 -> 41395.83
...

Sheet PAYSLIP (1st)
A2: PAY SLIP | J2: PAY SLIP | S2: PAY SLIP | AB2: PAY SLIP | AK2: PAY SLIP | AT2: PAY SLIP | BC2: PAY SLIP | BL2: PAY SLIP | BU2: PAY SLIP | CD2: PAY SLIP | CM2: PAY SLIP | CV2: PAY SLIP | DE2: PAY SLIP | DN2: PAY SLIP | DW2: PAY SLIP | EF2: PAY SLIP | EO2: PAY SLIP | EX2: PAY SLIP | FG2: PAY SLIP | FP2: PAY SLIP | FY2: PAY SLIP | GH2: PAY SLIP | GQ2: PAY SLIP | GZ2: PAY SLIP | HI2: PAY SLIP | HR2: PAY SLIP | IA2: PAY SLIP | IJ2: PAY SLIP | IS2: PAY SLIP | JB2: PAY SLIP | JK2: PAY SLIP | JT2: PAY SLIP | KC2: PAY SLIP
A4: Employee: | B4: 28 | C4: Morales, Marco B. | F4: Payroll period: | G4: 45946 | H4: 45961 | J4: Employee: | K4: 29 | L4: Uy, John Michael B. | O4: Payroll period: | P4: 45946 | Q4: 45961 | S4: Employee: | T4: 30 | U4: Lagrisola, Ralph Rafael A. | X4: Payroll period: | Y4: 45946 | Z4: 45961 | AB4: Employee: | AC4: 31 | AD4: Lim, John Christopher Tan | AG4: Payroll period: | AH4: 45946 | AI4: 45961 | AK4: Employee: | AL4: 32 | AM4: Quilao, Najma M. | AP4: Payroll period: | AQ4: 45946 | AR4: 45961 | AT4: Employee: | AU4: 33 | AV4: Balingit, John Dave V. | AY4: Payroll period: | AZ4: 45946 | BA4: 45961 | BC4: Employee: | BD4: 34 | BE4: Tolentino, Julius Angelito R. | BH4: Payroll period: | BI4: 45946 | BJ4: 45961 | BL4: Employee: | BM4: 35 | BN4: Hilario, Gilbert C. | BQ4: Payroll period: | BR4: 45946 | BS4: 45961 | BU4: Employee: | BV4: 1 | BW4: =VLOOKUP(BV4,'Raw Sheet'!$A$8:$BK$59,'Raw Sheet'!$C$4,FALSE) -> A | BZ4: Payroll period: | CA4: ='Payroll Register'!D3 -> 46023 | CB4: ='Payroll Register'!E3 -> 46037 | CD4: Employee: | CE4: 5 | CF4: =VLOOKUP(CE4,'Raw Sheet'!$A$8:$BK$59,'Raw Sheet'!$C$4,FALSE) -> #N/A | CI4: Payroll period: | CJ4: 45946 | CK4: 45961 | CM4: Employee: | CN4: 38 | CO4: Antalan, Rogelio G. | CR4: Payroll period: | CS4: 45946 | CT4: 45961 | CV4: Employee: | CW4: 8 | CX4: =VLOOKUP(CW4,'Raw Sheet'!$A$8:$BK$59,'Raw Sheet'!$C$4,FALSE) -> B | DA4: Payroll period: | DB4: ='Raw Sheet'!D2 -> 46023 | DC4: ='Raw Sheet'!E2 -> 46037 | DE4: Employee: | DF4: 40 | DG4: Frias, Ulric Vhon Vargas | DJ4: Payroll period: | DK4: 45946 | DL4: 45961 | DN4: Employee: | DO4: 10 | DP4: =VLOOKUP(DO4,'Raw Sheet'!$A$8:$BK$59,'Raw Sheet'!$C$4,FALSE) -> C | DS4: Payroll period: | DT4: ='Raw Sheet'!D2 -> 46023 | DU4: ='Raw Sheet'!E2 -> 46037 | DW4: Employee: | DX4: 11 | DY4: =VLOOKUP(DX4,'Raw Sheet'!$A$8:$BK$59,'Raw Sheet'!$C$4,FALSE) -> D | EB4: Payroll period: | EC4: ='Raw Sheet'!D2 -> 46023 | ED4: ='Raw Sheet'!E2 -> 46037 | EF4: Employee: | EG4: 12 | EH4: =VLOOKUP(EG4,'Raw Sheet'!$A$8:$BK$59,'Raw Sheet'!$C$4,FALSE) -> E | EK4: Payroll period: | EL4: ='Raw Sheet'!D2 -> 46023 | EM4: ='Raw Sheet'!E2 -> 46037 | EO4: Employee: | EP4: 15 | EQ4: =VLOOKUP(EP4,'Raw Sheet'!$A$8:$BK$59,'Raw Sheet'!$C$4,FALSE) -> F | ET4: Payroll period: | EU4: ='Raw Sheet'!D2 -> 46023 | EV4: ='Raw Sheet'!E2 -> 46037 | EX4: Employee: | EY4: 19 | EZ4: =VLOOKUP(EY4,'Raw Sheet'!$A$8:$BK$59,'Raw Sheet'!$C$4,FALSE) -> G | FC4: Payroll period: | FD4: ='Raw Sheet'!D2 -> 46023 | FE4: ='Raw Sheet'!E2 -> 46037 | FG4: Employee: | FH4: 36 | FI4: =VLOOKUP(FH4,'Raw Sheet'!$A$8:$BK$59,'Raw Sheet'!$C$4,FALSE) -> H | FL4: Payroll period: | FM4: ='Raw Sheet'!D2 -> 46023 | FN4: ='Raw Sheet'!E2 -> 46037 | FP4: Employee: | FQ4: 37 | FR4: =VLOOKUP(FQ4,'Raw Sheet'!$A$8:$BK$59,'Raw Sheet'!$C$4,FALSE) -> I | FU4: Payroll period: | FV4: ='Raw Sheet'!D2 -> 46023 | FW4: ='Raw Sheet'!E2 -> 46037 | FY4: Employee: | FZ4: 48 | GA4: Arias, William Wallace Lao | GD4: Payroll period: | GE4: 45946 | GF4: 45961 | GH4: Employee: | GI4: 39 | GJ4: =VLOOKUP(GI4,'Raw Sheet'!$A$8:$BK$59,'Raw Sheet'!$C$4,FALSE) -> J | GM4: Payroll period: | GN4: ='Raw Sheet'!D2 -> 46023 | GO4: ='Raw Sheet'!E2 -> 46037 | GQ4: Employee: | GR4: 41 | GS4: =VLOOKUP(GR4,'Raw Sheet'!$A$8:$BK$59,'Raw Sheet'!$C$4,FALSE) -> K | GV4: Payroll period: | GW4: ='Raw Sheet'!D2 -> 46023 | GX4: ='Raw Sheet'!E2 -> 46037 | GZ4: Employee: | HA4: 42 | HB4: =VLOOKUP(HA4,'Raw Sheet'!$A$8:$BK$59,'Raw Sheet'!$C$4,FALSE) -> L | HE4: Payroll period: | HF4: ='Raw Sheet'!D2 -> 46023 | HG4: ='Raw Sheet'!E2 -> 46037 | HI4: Employee: | HJ4: 43 | HK4: =VLOOKUP(HJ4,'Raw Sheet'!$A$8:$BK$59,'Raw Sheet'!$C$4,FALSE) -> M | HN4: Payroll period: | HO4: ='Raw Sheet'!D2 -> 46023 | HP4: ='Raw Sheet'!E2 -> 46037 | HR4: Employee: | HS4: 44 | HT4: =VLOOKUP(HS4,'Raw Sheet'!$A$8:$BK$59,'Raw Sheet'!$C$4,FALSE) -> N | HW4: Payroll period: | HX4: ='Raw Sheet'!$D$2 -> 46023 | HY4: ='Raw Sheet'!$E$2 -> 46037 | IA4: Employee: | IB4: 45 | IC4: =VLOOKUP(IB4,'Raw Sheet'!$A$8:$BK$59,'Raw Sheet'!$C$4,FALSE) -> O | IF4: Payroll period: | IG4: ='Raw Sheet'!$D$2 -> 46023 | IH4: ='Raw Sheet'!$E$2 -> 46037 | IJ4: Employee: | IK4: 46 | IL4: =VLOOKUP(IK4,'Raw Sheet'!$A$8:$BK$59,'Raw Sheet'!$C$4,FALSE) -> P | IO4: Payroll period: | IP4: ='Raw Sheet'!$D$2 -> 46023 | IQ4: ='Raw Sheet'!$E$2 -> 46037 | IS4: Employee: | IT4: 47 | IU4: =VLOOKUP(IT4,'Raw Sheet'!$A$8:$BK$59,'Raw Sheet'!$C$4,FALSE) -> Q | IX4: Payroll period: | IY4: ='Raw Sheet'!$D$2 -> 46023 | IZ4: ='Raw Sheet'!$E$2 -> 46037 | JB4: Employee: | JC4: 49 | JD4: =VLOOKUP(JC4,'Raw Sheet'!$A$8:$BK$59,'Raw Sheet'!$C$4,FALSE) -> R | JG4: Payroll period: | JH4: ='Raw Sheet'!$D$2 -> 46023 | JI4: ='Raw Sheet'!$E$2 -> 46037 | JK4: Employee: | JL4: 50 | JM4: =VLOOKUP(JL4,'Raw Sheet'!$A$8:$BK$59,'Raw Sheet'!$C$4,FALSE) -> S | JP4: Payroll period: | JQ4: ='Raw Sheet'!$D$2 -> 46023 | JR4: ='Raw Sheet'!$E$2 -> 46037 | JT4: Employee: | JU4: 51 | JV4: =VLOOKUP(JU4,'Raw Sheet'!$A$8:$BK$59,'Raw Sheet'!$C$4,FALSE) -> T | JY4: Payroll period: | JZ4: ='Raw Sheet'!$D$2 -> 46023 | KA4: ='Raw Sheet'!$E$2 -> 46037 | KC4: Employee: | KD4: 52 | KE4: =VLOOKUP(KD4,'Raw Sheet'!$A$8:$BK$59,'Raw Sheet'!$C$4,FALSE) -> U | KH4: Payroll period: | KI4: ='Raw Sheet'!$D$2 -> 46023 | KJ4: ='Raw Sheet'!$E$2 -> 46037
A5: Position: | B5: Technical Support Engineer – L2 | J5: Position: | K5: Technical Support Engineer – L2 | S5: Position: | T5: Technical Support Engineer – L2 | AB5: Position: | AC5: Senior Service Lead - Technical Support | AK5: Position: | AL5: Service Desk Analyst L-1 | AT5: Position: | AU5: Technical Support Engineer – L2 | BC5: Position: | BD5: Technical Support Engineer – L2 | BL5: Position: | BM5: Technical Support Engineer – L2 | BU5: Position: | BV5: =VLOOKUP(BV4,'Raw Sheet'!$A$8:$BK$28,'Raw Sheet'!$F$4,FALSE) -> Service Desk Analyst-L1 | CD5: Position: | CE5: =VLOOKUP(CE4,'Raw Sheet'!$A$8:$BK$28,'Raw Sheet'!$F$4,FALSE) -> #N/A | CM5: Position: | CN5: Senior Security Analyst | CV5: Position: | CW5: =VLOOKUP(CW4,'Raw Sheet'!$A$8:$BK$28,'Raw Sheet'!$F$4,FALSE) -> Service Desk Analyst-L1 | DE5: Position: | DF5: Service Desk Analyst L-1 | DN5: Position: | DO5: =VLOOKUP(DO4,'Raw Sheet'!$A$8:$BK$28,'Raw Sheet'!$F$4,FALSE) -> Service Desk Analyst-L1 | DW5: Position: | DX5: =VLOOKUP(DX4,'Raw Sheet'!$A$8:$BK$28,'Raw Sheet'!$F$4,FALSE) -> Senior Operations Manager | EF5: Position: | EG5: =VLOOKUP(EG4,'Raw Sheet'!$A$8:$BK$28,'Raw Sheet'!$F$4,FALSE) -> Senior Project Manager | EO5: Position: | EP5: =VLOOKUP(EP4,'Raw Sheet'!$A$8:$BK$28,'Raw Sheet'!$F$4,FALSE) -> Service Desk Analyst-L1 | EX5: Position: | EY5: =VLOOKUP(EY4,'Raw Sheet'!$A$8:$BK$28,'Raw Sheet'!$F$4,FALSE) -> Service Desk Analyst-L1 | FG5: Position: | FH5: =VLOOKUP(FH4,'Raw Sheet'!$A$8:$BK$28,'Raw Sheet'!$F$4,FALSE) -> Senior Security Analyst | FP5: Position: | FQ5: =VLOOKUP(FQ4,'Raw Sheet'!$A$8:$BK$28,'Raw Sheet'!$F$4,FALSE) -> Lead Security Analyst | FY5: Position: | FZ5: Senior Security Analyst | GH5: Position: | GI5: =VLOOKUP(GI4,'Raw Sheet'!$A$8:$BK$28,'Raw Sheet'!$F$4,FALSE) -> Service Desk Analyst L-1 | GQ5: Position: | GR5: =VLOOKUP(GR4,'Raw Sheet'!$A$8:$BK$28,'Raw Sheet'!$F$4,FALSE) -> Service Desk Analyst L-1 | GZ5: Position: | HA5: =VLOOKUP(HA4,'Raw Sheet'!$A$8:$BK$28,'Raw Sheet'!$F$4,FALSE) -> Lead Security Analyst | HI5: Position: | HJ5: =VLOOKUP(HJ4,'Raw Sheet'!$A$8:$BK$28,'Raw Sheet'!$F$4,FALSE) -> Senior Security Analyst | HR5: Position: | HS5: =VLOOKUP(HS4,'Raw Sheet'!$A$8:$BK$28,'Raw Sheet'!$F$4,FALSE) -> Service Desk Analyst-L1 | IA5: Position: | IB5: =VLOOKUP(IB4,'Raw Sheet'!$A$8:$BK$28,'Raw Sheet'!$F$4,FALSE) -> Senior Security Analyst | IJ5: Position: | IK5: =VLOOKUP(IK4,'Raw Sheet'!$A$8:$BK$28,'Raw Sheet'!$F$4,FALSE) -> Senior Security Analyst | IS5: Position: | IT5: =VLOOKUP(IT4,'Raw Sheet'!$A$8:$BK$28,'Raw Sheet'!$F$4,FALSE) -> Service Desk Analyst L-1 | JB5: Position: | JC5: =VLOOKUP(JC4,'Raw Sheet'!$A$8:$BK$28,'Raw Sheet'!$F$4,FALSE) -> Service Desk Analyst L-1 | JK5: Position: | JL5: =VLOOKUP(JL4,'Raw Sheet'!$A$8:$BK$28,'Raw Sheet'!$F$4,FALSE) -> Senior Security Analyst | JT5: Position: | JU5: =VLOOKUP(JU4,'Raw Sheet'!$A$8:$BK$28,'Raw Sheet'!$F$4,FALSE) -> Service Desk Analyst L-1 | KC5: Position: | KD5: =VLOOKUP(KD4,'Raw Sheet'!$A$8:$BK$28,'Raw Sheet'!$F$4,FALSE) -> Service Desk Analyst L-1
A7: REGULAR EARNINGS | E7: TAXABLE OTHER EARNINGS | G7: NON-TAXABLE OTHER EARNINGS | J7: REGULAR EARNINGS | N7: TAXABLE OTHER EARNINGS | P7: NON-TAXABLE OTHER EARNINGS | S7: REGULAR EARNINGS | W7: TAXABLE OTHER EARNINGS | Y7: NON-TAXABLE OTHER EARNINGS | AB7: REGULAR EARNINGS | AF7: TAXABLE OTHER EARNINGS | AH7: NON-TAXABLE OTHER EARNINGS | AK7: REGULAR EARNINGS | AO7: TAXABLE OTHER EARNINGS | AQ7: NON-TAXABLE OTHER EARNINGS | AT7: REGULAR EARNINGS | AX7: TAXABLE OTHER EARNINGS | AZ7: NON-TAXABLE OTHER EARNINGS | BC7: REGULAR EARNINGS | BG7: TAXABLE OTHER EARNINGS | BI7: NON-TAXABLE OTHER EARNINGS | BL7: REGULAR EARNINGS | BP7: TAXABLE OTHER EARNINGS | BR7: NON-TAXABLE OTHER EARNINGS | BU7: REGULAR EARNINGS | BY7: TAXABLE OTHER EARNINGS | CA7: NON-TAXABLE OTHER EARNINGS | CD7: REGULAR EARNINGS | CH7: TAXABLE OTHER EARNINGS | CJ7: NON-TAXABLE OTHER EARNINGS | CM7: REGULAR EARNINGS | CQ7: TAXABLE OTHER EARNINGS | CS7: NON-TAXABLE OTHER EARNINGS | CV7: REGULAR EARNINGS | CZ7: TAXABLE OTHER EARNINGS | DB7: NON-TAXABLE OTHER EARNINGS | DE7: REGULAR EARNINGS | DI7: TAXABLE OTHER EARNINGS | DK7: NON-TAXABLE OTHER EARNINGS | DN7: REGULAR EARNINGS | DR7: TAXABLE OTHER EARNINGS | DT7: NON-TAXABLE OTHER EARNINGS | DW7: REGULAR EARNINGS | EA7: TAXABLE OTHER EARNINGS | EC7: NON-TAXABLE OTHER EARNINGS | EF7: REGULAR EARNINGS | EJ7: TAXABLE OTHER EARNINGS | EL7: NON-TAXABLE OTHER EARNINGS | EO7: REGULAR EARNINGS | ES7: TAXABLE OTHER EARNINGS | EU7: NON-TAXABLE OTHER EARNINGS | EX7: REGULAR EARNINGS | FB7: TAXABLE OTHER EARNINGS | FD7: NON-TAXABLE OTHER EARNINGS | FG7: REGULAR EARNINGS | FK7: TAXABLE OTHER EARNINGS | FM7: NON-TAXABLE OTHER EARNINGS | FP7: REGULAR EARNINGS | FT7: TAXABLE OTHER EARNINGS | FV7: NON-TAXABLE OTHER EARNINGS | FY7: REGULAR EARNINGS | GC7: TAXABLE OTHER EARNINGS | GE7: NON-TAXABLE OTHER EARNINGS | GH7: REGULAR EARNINGS | GL7: TAXABLE OTHER EARNINGS | GN7: NON-TAXABLE OTHER EARNINGS | GQ7: REGULAR EARNINGS | GU7: TAXABLE OTHER EARNINGS | GW7: NON-TAXABLE OTHER EARNINGS | GZ7: REGULAR EARNINGS | HD7: TAXABLE OTHER EARNINGS | HF7: NON-TAXABLE OTHER EARNINGS | HI7: REGULAR EARNINGS | HM7: TAXABLE OTHER EARNINGS | HO7: NON-TAXABLE OTHER EARNINGS | HR7: REGULAR EARNINGS | HV7: TAXABLE OTHER EARNINGS | HX7: NON-TAXABLE OTHER EARNINGS | IA7: REGULAR EARNINGS | IE7: TAXABLE OTHER EARNINGS | IG7: NON-TAXABLE OTHER EARNINGS | IJ7: REGULAR EARNINGS | IN7: TAXABLE OTHER EARNINGS | IP7: NON-TAXABLE OTHER EARNINGS | IS7: REGULAR EARNINGS | IW7: TAXABLE OTHER EARNINGS | IY7: NON-TAXABLE OTHER EARNINGS | JB7: REGULAR EARNINGS | JF7: TAXABLE OTHER EARNINGS | JH7: NON-TAXABLE OTHER EARNINGS | JK7: REGULAR EARNINGS | JO7: TAXABLE OTHER EARNINGS | JQ7: NON-TAXABLE OTHER EARNINGS | JT7: REGULAR EARNINGS | JX7: TAXABLE OTHER EARNINGS | JZ7: NON-TAXABLE OTHER EARNINGS | KC7: REGULAR EARNINGS | KG7: TAXABLE OTHER EARNINGS | KI7: NON-TAXABLE OTHER EARNINGS
C8: Days/Hours | D8: Amount | L8: Days/Hours | M8: Amount | U8: Days/Hours | V8: Amount | AD8: Days/Hours | AE8: Amount | AM8: Days/Hours | AN8: Amount | AV8: Days/Hours | AW8: Amount | BE8: Days/Hours | BF8: Amount | BN8: Days/Hours | BO8: Amount | BW8: Days/Hours | BX8: Amount | CF8: Days/Hours | CG8: Amount | CO8: Days/Hours | CP8: Amount | CX8: Days/Hours | CY8: Amount | DG8: Days/Hours | DH8: Amount | DP8: Days/Hours | DQ8: Amount | DY8: Days/Hours | DZ8: Amount | EH8: Days/Hours | EI8: Amount | EQ8: Days/Hours | ER8: Amount | EZ8: Days/Hours | FA8: Amount | FI8: Days/Hours | FJ8: Amount | FR8: Days/Hours | FS8: Amount | GA8: Days/Hours | GB8: Amount | GJ8: Days/Hours | GK8: Amount | GS8: Days/Hours | GT8: Amount | HB8: Days/Hours | HC8: Amount | HK8: Days/Hours | HL8: Amount | HT8: Days/Hours | HU8: Amount | IC8: Days/Hours | ID8: Amount | IL8: Days/Hours | IM8: Amount | IU8: Days/Hours | IV8: Amount | JD8: Days/Hours | JE8: Amount | JM8: Days/Hours | JN8: Amount | JV8: Days/Hours | JW8: Amount | KE8: Days/Hours | KF8: Amount
A9: Basic pay: | D9: 0 | J9: Basic pay: | M9: 0 | S9: Basic pay: | V9: 0 | AB9: Basic pay: | AE9: 0 | AK9: Basic pay: | AN9: 0 | AQ9: De Minimis Benefit | AR9: #REF! | AT9: Basic pay: | AW9: 0 | AZ9: De Minimis Benefit | BA9: 0 | BC9: Basic pay: | BF9: 0 | BI9: De Minimis Benefit | BJ9: #REF! | BL9: Basic pay: | BO9: 0 | BR9: De Minimis Benefit | BS9: #REF! | BU9: Basic pay: | BX9: =VLOOKUP(BV$4,'Raw Sheet'!$A$8:$BK$59,'Raw Sheet'!$H$4,FALSE) -> 18600 | CA9: De Minimis Benefit | CB9: ='Payroll Register'!T8 -> 1400 | CD9: Basic pay: | CG9: =VLOOKUP(CE$4,'Raw Sheet'!$A$8:$BK$59,'Raw Sheet'!$H$4,FALSE) -> #N/A | CM9: Basic pay: | CP9: 0 | CS9: De Minimis Benefit | CT9: #REF! | CV9: Basic pay: | CY9: =VLOOKUP(CW$4,'Raw Sheet'!$A$8:$BK$59,'Raw Sheet'!$H$4,FALSE) -> 22500 | DE9: Basic pay: | DH9: 0 | DK9: De Minimis Benefit | DL9: #REF! | DN9: Basic pay: | DQ9: =VLOOKUP(DO$4,'Raw Sheet'!$A$8:$BK$59,'Raw Sheet'!$H$4,FALSE) -> 21000 | DT9: De Minimis Benefit | DU9: ='Payroll Register'!T10 -> 1050 | DW9: Basic pay: | DZ9: =VLOOKUP(DX$4,'Raw Sheet'!$A$8:$BK$59,'Raw Sheet'!$H$4,FALSE) -> 84800 | EC9: De Minimis Benefit | ED9: 1400 | EF9: Basic pay: | EI9: =VLOOKUP(EG$4,'Raw Sheet'!$A$8:$BK$59,'Raw Sheet'!$H$4,FALSE) -> 127800 | EL9: De Minimis Benefit | EM9: 1400 | EO9: Basic pay: | ER9: =VLOOKUP(EP$4,'Raw Sheet'!$A$8:$BK$59,'Raw Sheet'!$H$4,FALSE) -> 13000 | EU9: De Minimis Benefit | EV9: ='Payroll Register'!T13 -> 780 | EX9: Basic pay: | FA9: =VLOOKUP(EY$4,'Raw Sheet'!$A$8:$BK$59,'Raw Sheet'!$H$4,FALSE) -> 14840 | FD9: De Minimis Benefit | FE9: 1400 | FG9: Basic pay: | FJ9: =VLOOKUP(FH$4,'Raw Sheet'!$A$8:$BK$59,'Raw Sheet'!$H$4,FALSE) -> 45050 | FM9: De Minimis Benefit | FN9: 1400 | FP9: Basic pay: | FS9: =VLOOKUP(FQ$4,'Raw Sheet'!$A$8:$BK$59,'Raw Sheet'!$H$4,FALSE) -> 66562.5 | FV9: De Minimis Benefit | FW9: 1400 | FY9: Basic pay: | GB9: 0 | GE9: De Minimis Benefit | GF9: #REF! | GH9: Basic pay: | GK9: =VLOOKUP(GI$4,'Raw Sheet'!$A$8:$BK$59,'Raw Sheet'!$H$4,FALSE) -> 13125 | GN9: De Minimis Benefit | GO9: 1400 | GQ9: Basic pay: | GT9: =VLOOKUP(GR$4,'Raw Sheet'!$A$8:$BK$59,'Raw Sheet'!$H$4,FALSE) -> 14323 | GW9: De Minimis Benefit | GX9: 1400 | GZ9: Basic pay: | HC9: =VLOOKUP(HA$4,'Raw Sheet'!$A$8:$BK$59,'Raw Sheet'!$H$4,FALSE) -> 93750 | HF9: De Minimis Benefit | HG9: 1400 | HI9: Basic pay: | HL9: =VLOOKUP(HJ$4,'Raw Sheet'!$A$8:$BK$59,'Raw Sheet'!$H$4,FALSE) -> 51408 | HO9: De Minimis Benefit | HP9: 1400 | HR9: Basic pay: | HU9: =VLOOKUP(HS$4,'Raw Sheet'!$A$8:$BK$59,'Raw Sheet'!$H$4,FALSE) -> 12350 | HX9: De Minimis Benefit | HY9: 1400 | IA9: Basic pay: | ID9: =VLOOKUP(IB$4,'Raw Sheet'!$A$8:$BK$59,'Raw Sheet'!$H$4,FALSE) -> 42500 | IG9: De Minimis Benefit | IH9: 1400 | IJ9: Basic pay: | IM9: =VLOOKUP(IK$4,'Raw Sheet'!$A$8:$BK$59,'Raw Sheet'!$H$4,FALSE) -> 65000 | IP9: De Minimis Benefit | IQ9: 1400 | IS9: Basic pay: | IV9: =VLOOKUP(IT$4,'Raw Sheet'!$A$8:$BK$59,'Raw Sheet'!$H$4,FALSE) -> 15000 | IY9: De Minimis Benefit | IZ9: 1400 | JB9: Basic pay: | JE9: =VLOOKUP(JC$4,'Raw Sheet'!$A$8:$BK$59,'Raw Sheet'!$H$4,FALSE) -> 14000 | JH9: De Minimis Benefit | JI9: 1400 | JK9: Basic pay: | JN9: =VLOOKUP(JL$4,'Raw Sheet'!$A$8:$BK$59,'Raw Sheet'!$H$4,FALSE) -> 42500 | JQ9: De Minimis Benefit | JR9: 1400 | JT9: Basic pay: | JW9: =VLOOKUP(JU$4,'Raw Sheet'!$A$8:$BK$59,'Raw Sheet'!$H$4,FALSE) -> 11000 | JZ9: De Minimis Benefit | KA9: 1400 | KC9: Basic pay: | KF9: =VLOOKUP(KD$4,'Raw Sheet'!$A$8:$BK$59,'Raw Sheet'!$H$4,FALSE) -> 9000 | KI9: De Minimis Benefit | KJ9: 1400
A10: Rate per hour | C10: 0 | J10: Rate per hour | L10: 0 | S10: Rate per hour | U10: 0 | AB10: Rate per hour | AD10: 0 | AK10: Rate per hour | AM10: 0 | AT10: Rate per hour | AV10: 0 | BC10: Rate per hour | BE10: 0 | BL10: Rate per hour | BN10: 0 | BU10: Rate per hour | BW10: =VLOOKUP(BV4,'Raw Sheet'!$A$8:$BK$59,'Raw Sheet'!$J$4,FALSE) -> 213.7931 | CD10: Rate per hour | CF10: =VLOOKUP(CE4,'Raw Sheet'!$A$8:$BK$59,'Raw Sheet'!$J$4,FALSE) -> #N/A | CM10: Rate per hour | CO10: 0 | CV10: Rate per hour | CX10: =VLOOKUP(CW4,'Raw Sheet'!$A$8:$BK$59,'Raw Sheet'!$J$4,FALSE) -> 258.62069 | DE10: Rate per hour | DG10: 0 | DN10: Rate per hour | DP10: =VLOOKUP(DO4,'Raw Sheet'!$A$8:$BK$59,'Raw Sheet'!$J$4,FALSE) -> 241.37931 | DW10: Rate per hour | DY10: =VLOOKUP(DX4,'Raw Sheet'!$A$8:$BK$59,'Raw Sheet'!$J$4,FALSE) -> 974.71264 | EF10: Rate per hour | EH10: =VLOOKUP(EG4,'Raw Sheet'!$A$8:$BK$59,'Raw Sheet'!$J$4,FALSE) -> 1468.9655 | EO10: Rate per hour | EQ10: =VLOOKUP(EP4,'Raw Sheet'!$A$8:$BK$59,'Raw Sheet'!$J$4,FALSE) -> 149.42529 | EU10: 2025 Tax Refund | EV10: ='Payroll Register'!AK13 -> 4333.3366 | EX10: Rate per hour | EZ10: =VLOOKUP(EY4,'Raw Sheet'!$A$8:$BK$59,'Raw Sheet'!$J$4,FALSE) -> 170.57471 | FG10: Rate per hour | FI10: =VLOOKUP(FH4,'Raw Sheet'!$A$8:$BK$59,'Raw Sheet'!$J$4,FALSE) -> 517.81609 | FP10: Rate per hour | FR10: =VLOOKUP(FQ4,'Raw Sheet'!$A$8:$BK$59,'Raw Sheet'!$J$4,FALSE) -> 765.08621 | FY10: Rate per hour | GA10: 0 | GH10: Rate per hour | GJ10: =VLOOKUP(GI4,'Raw Sheet'!$A$8:$BK$59,'Raw Sheet'!$J$4,FALSE) -> 150.86207 | GQ10: Rate per hour | GS10: =VLOOKUP(GR4,'Raw Sheet'!$A$8:$BK$59,'Raw Sheet'!$J$4,FALSE) -> 164.63218 | GZ10: Rate per hour | HB10: =VLOOKUP(HA4,'Raw Sheet'!$A$8:$BK$59,'Raw Sheet'!$J$4,FALSE) -> 1077.5862 | HI10: Rate per hour | HK10: =VLOOKUP(HJ4,'Raw Sheet'!$A$8:$BK$59,'Raw Sheet'!$J$4,FALSE) -> 590.89655 | HR10: Rate per hour | HT10: =VLOOKUP(HS4,'Raw Sheet'!$A$8:$BK$59,'Raw Sheet'!$J$4,FALSE) -> 141.95402 | IA10: Rate per hour | IC10: =VLOOKUP(IB4,'Raw Sheet'!$A$8:$BK$59,'Raw Sheet'!$J$4,FALSE) -> 488.50575 | IJ10: Rate per hour | IL10: =VLOOKUP(IK4,'Raw Sheet'!$A$8:$BK$59,'Raw Sheet'!$J$4,FALSE) -> 747.12644 | IS10: Rate per hour | IU10: =VLOOKUP(IT4,'Raw Sheet'!$A$8:$BK$59,'Raw Sheet'!$J$4,FALSE) -> 172.41379 | JB10: Rate per hour | JD10: =VLOOKUP(JC4,'Raw Sheet'!$A$8:$BK$59,'Raw Sheet'!$J$4,FALSE) -> 160.91954 | JK10: Rate per hour | JM10: =VLOOKUP(JL4,'Raw Sheet'!$A$8:$BK$59,'Raw Sheet'!$J$4,FALSE) -> 488.50575 | JT10: Rate per hour | JV10: =VLOOKUP(JU4,'Raw Sheet'!$A$8:$BK$59,'Raw Sheet'!$J$4,FALSE) -> 126.43678 | KC10: Rate per hour | KE10: =VLOOKUP(KD4,'Raw Sheet'!$A$8:$BK$59,'Raw Sheet'!$J$4,FALSE) -> 103.44828
A11: No. of hours Worked: | C11: 96 | J11: No. of hours Worked: | L11: 96 | S11: No. of hours Worked: | U11: 96 | AB11: No. of hours Worked: | AD11: 96 | AK11: No. of hours Worked: | AM11: 96 | AT11: No. of hours Worked: | AV11: 96 | BC11: No. of hours Worked: | BE11: 96 | BL11: No. of hours Worked: | BN11: 96 | BU11: No. of hours Worked: | BW11: =VLOOKUP(BV4,'Raw Sheet'!$A$8:$BK$28,63,FALSE) -> 72 | CD11: No. of hours Worked: | CF11: =VLOOKUP(CF4,'Raw Sheet'!L:BT,60,0) -> #N/A | CM11: No. of hours Worked: | CO11: 96 | CV11: No. of hours Worked: | CX11: =VLOOKUP(CW4,'Raw Sheet'!$A$8:$BK$28,63,0) -> 80 | DE11: No. of hours Worked: | DG11: 96 | DN11: No. of hours Worked: | DP11: =VLOOKUP(DO4,'Raw Sheet'!$A$8:$BK$28,63,0) -> 80 | DW11: No. of hours Worked: | DY11: =VLOOKUP(DX4,'Raw Sheet'!$A$8:$BK$28,63,0) -> 80 | EF11: No. of hours Worked: | EH11: =VLOOKUP(EG4,'Raw Sheet'!$A$8:$BK$28,63,0) -> 72 | EO11: No. of hours Worked: | EQ11: =VLOOKUP(EP4,'Raw Sheet'!$A$8:$BK$28,63,0) -> 80 | EX11: No. of hours Worked: | EZ11: =VLOOKUP(EY4,'Raw Sheet'!$A$8:$BK$28,63,0) -> 76 | FG11: No. of hours Worked: | FI11: =VLOOKUP(FH4,'Raw Sheet'!$A$8:$BK$28,63,0) -> 80 | FP11: No. of hours Worked: | FR11: =VLOOKUP(FR4,'Raw Sheet'!C:BK,60,0) -> 0 | FY11: No. of hours Worked: | GA11: 96 | GH11: No. of hours Worked: | GJ11: =VLOOKUP(GJ4,'Raw Sheet'!C:BK,60,0) -> 0 | GQ11: No. of hours Worked: | GS11: =VLOOKUP(GS4,'Raw Sheet'!C:BK,60,0) -> 0 | GZ11: No. of hours Worked: | HB11: =VLOOKUP(HB4,'Raw Sheet'!C:BK,60,0) -> 0 | HI11: No. of hours Worked: | HK11: ='Raw Sheet'!BK20 -> 0 | HR11: No. of hours Worked: | HT11: =VLOOKUP(HT4,'Raw Sheet'!C:BK,60,0) -> 0 | IA11: No. of hours Worked: | IC11: =VLOOKUP(IC4,'Raw Sheet'!C:BK,60,0) -> 0 | IJ11: No. of hours Worked: | IL11: =VLOOKUP(IL4,'Raw Sheet'!C:BK,60,0) -> 0 | IS11: No. of hours Worked: | IU11: =VLOOKUP(IU4,'Raw Sheet'!C:BK,60,0) -> -1379.3103 | JB11: No. of hours Worked: | JD11: =VLOOKUP(JD4,'Raw Sheet'!C:BK,60,0) -> 0 | JK11: No. of hours Worked: | JM11: =VLOOKUP(JM4,'Raw Sheet'!C:BK,60,0) -> 0 | JT11: No. of hours Worked: | JV11: ='Raw Sheet'!BK27 -> 68 | KC11: No. of hours Worked: | KE11: =VLOOKUP(KE4,'Raw Sheet'!C:BK,60,0) -> 0
A12: Night premium | C12: 0 | D12: =C10*10%*C12 -> 0 | J12: Night premium | L12: 0 | M12: =L10*10%*L12 -> 0 | S12: Night premium | U12: 0 | V12: =U10*10%*U12 -> 0 | AB12: Night premium | AD12: 0 | AE12: =AD10*10%*AD12 -> 0 | AK12: Night premium | AM12: 22 | AN12: =AM10*10%*AM12 -> 0 | AT12: Night premium | AV12: 22 | AW12: =AV10*10%*AV12 -> 0 | BC12: Night premium | BE12: 22 | BF12: =BE10*10%*BE12 -> 0 | BL12: Night premium | BN12: 22 | BO12: =BN10*10%*BN12 -> 0 | BU12: Night premium | BW12: =VLOOKUP(BV4,'Raw Sheet'!$A$8:$AI$28,35,0) -> 12 | BX12: =BW10*10%*BW12 -> 256.55172 | CD12: Night premium | CF12: 6 | CG12: =CF10*10%*CF12 -> #N/A | CM12: Night premium | CO12: 0 | CP12: =CO10*10%*CO12 -> 0 | CV12: Night premium | CX12: =VLOOKUP(CW4,'Raw Sheet'!$A$8:$AI$28,35,0) -> 30 | CY12: ='Payroll Register'!O9 -> 879.31034 | DE12: Night premium | DG12: 0 | DH12: =DG10*10%*DG12 -> 0 | DN12: Night premium | DP12: ='Raw Sheet'!AI10+'Raw Sheet'!AO10+'Raw Sheet'!BA10+'Raw Sheet'!BG10 -> 0 | DQ12: =DP10*10%*DP12 -> 0 | DW12: Night premium | DY12: ='Raw Sheet'!AI11+'Raw Sheet'!AO11+'Raw Sheet'!BA11+'Raw Sheet'!BG11 -> 0 | DZ12: =DY10*10%*DY12 -> 0 | EF12: Night premium | EH12: ='Raw Sheet'!AI12+'Raw Sheet'!AO12+'Raw Sheet'!BA12+'Raw Sheet'!BG12 -> 0 | EI12: =EH10*10%*EH12 -> 0 | EO12: Night premium | EQ12: ='Raw Sheet'!AI13+'Raw Sheet'!AO13+'Raw Sheet'!BA13+'Raw Sheet'!BG13 -> 0 | ER12: =EQ10*10%*EQ12 -> 0 | EX12: Night premium | EZ12: =VLOOKUP(EY4,'Raw Sheet'!A8:AI28,35,0) -> 9 | FA12: ='Payroll Register'!O14 -> 187.63218 | FG12: Night premium | FI12: ='Raw Sheet'!AI15+'Raw Sheet'!AO15+'Raw Sheet'!BA15+'Raw Sheet'!BG15 -> 0 | FJ12: =FI10*10%*FI12 -> 0 | FP12: Night premium | FR12: ='Raw Sheet'!AI16+'Raw Sheet'!AO16+'Raw Sheet'!BA16+'Raw Sheet'!BG16 -> 40 | FS12: =FR10*10%*FR12 -> 3060.3448 | FY12: Night premium | GA12: 32 | GB12: =GA10*10%*GA12 -> 0 | GH12: Night premium | GJ12: ='Raw Sheet'!AI17+'Raw Sheet'!AO17+'Raw Sheet'!BG17 -> 86 | GK12: =GJ10*10%*GJ12 -> 1297.4138 | GQ12: Night premium | GS12: ='Raw Sheet'!AI18+'Raw Sheet'!AO18+'Raw Sheet'!BG18 -> 80 | GT12: =GS10*10%*GS12 -> 1317.0575 | GZ12: Night premium | HB12: ='Raw Sheet'!AI19 -> 20 | HC12: ='Payroll Register'!O19 -> 2155.1724 | HI12: Night premium | HK12: ='Raw Sheet'!AI20+'Raw Sheet'!AO20+'Raw Sheet'!BG20 -> 0 | HL12: =HK10*10%*HK12 -> 0 | HR12: Night premium | HT12: ='Raw Sheet'!AI21+'Raw Sheet'!AO21+'Raw Sheet'!BG21 -> 64 | HU12: =HT10*10%*HT12 -> 908.50575 | IA12: Night premium | IC12: ='Raw Sheet'!AI22+'Raw Sheet'!AO22+'Raw Sheet'!BG22 -> 72 | ID12: =IC10*10%*IC12 -> 3517.2414 | IJ12: Night premium | IL12: ='Raw Sheet'!AI23+'Raw Sheet'!AO23+'Raw Sheet'!BG23 -> 48 | IM12: =IL10*10%*IL12 -> 3586.2069 | IS12: Night premium | IU12: ='Raw Sheet'!AI24+'Raw Sheet'!AO24+'Raw Sheet'!BG24 -> 16 | IV12: =IU10*10%*IU12 -> 275.86207 | JB12: Night premium | JD12: ='Raw Sheet'!AI25+'Raw Sheet'!AO25+'Raw Sheet'!BG25 -> 20 | JE12: =JD10*10%*JD12 -> 321.83908 | JK12: Night premium | JM12: ='Raw Sheet'!AI26+'Raw Sheet'!AO26+'Raw Sheet'!BG26 -> 32 | JN12: =JM10*10%*JM12 -> 1563.2184 | JT12: Night premium | JV12: ='Raw Sheet'!AI27+'Raw Sheet'!AO27+'Raw Sheet'!BG27 -> 24 | JW12: =JV10*10%*JV12 -> 303.44828 | KC12: Night premium | KE12: ='Raw Sheet'!AI28+'Raw Sheet'!AO28+'Raw Sheet'!BG28 -> 22 | KF12: =KE10*10%*KE12 -> 227.58621
